Workbook
Name ProjectOptions: 'Input''s from BD(Sales)'!$B$167:$D$200
Name Railing: 'Bidcell BOM (LTS)'!#REF!
Name TN_NOC: 'Bidcell BOM (LTS)'!$A$597:$B$612

Sheet Input's from BD(Sales)
C1: DOC. No: 4PEL/DES-SSR/109 #I01, R05.
C2: Issue Date: 23/02/2026. | P2: Client Scope | Q2: Client Scope | R2: Ground | S2: Cable Tray | T2: Required | U2: Domestic | V2: Client Scope | W2: Client Scope
C3: Control Copy No. 02. | P3: Trenching | Q3: Not Required | R3: Roof | S3: Client Scope | T3: Not Required | U3: Imported | V3: Already Exist | W3: 4PEL Scope
A4: Site Surrvey Request Form | P4: Existing Trench | Q4: 4PEL Scope | S4: Trenching | V4: 4PEL Scope | W4: Not Required
A5: Site Visit Request Form (To be filled by Sales Team) | C5: Remarks | D5: Remarks | P5: Cable Tray | V5: Not Required
A6: Name of BD Person | B6: Carl Aaron
A7: Mobile No. | B7: 9551062519
A8: Mail id | B8: carl.aaron@fourthpartner.co
A9: Site visit Request date
A10: State | B10: Maharashtra | C10: =IF(B10<>"","","Please fill the State to access further details")
A11: Client name | B11: West Pioneer Properties
A12: Mode of site survey | B12: Physical
A13: Location & address | B13: Metro Junction Mall, Kalyan - Shilphata Rd, Kalyan East, Kalyan, Maharashtra 421306
A14: Lat & Long details | B14: 19°13'45.98"N 73°07'23.94"E
A15: This Project having RFQ/RFP | B15: Yes | C15: =IF(B15<>"","","Further details to RFP/RFQ can be accessed only if RFP/RFQ details are filled")
A16: Plant Type (Capex/Opex) | B16: Capex
A17: Expected Cap in Kwp | B17: 400
A18: No. of locations | B18: 1
A19: Type of installation | B19: RCC
A20: Module wattage (Wp) | B20: 595 / 590 / 585
A21: Module Origin | B21: ALMM Approved
A22: Prefered Inverter make | B22: Solis / Sungrow / Equivalent
A23: DC/AC Ratio
A24: AMC & Module Cleaning | C24: =B16 & " Model" -> Capex Model
A25: No. of Years of AMC & Module cleaning | C25: =C24 -> Capex Model
A26: PBG Amount % | C26: =C25 -> Capex Model
A27: No. of Yrs BG is required to be maintained | C27: =C26 -> Capex Model
A28: Marketing Commission % | B28: 0 | C28: ='Bidcell BOM (LTS)'!F387 -> 0 | D28: /Wp
A29: EPC Margin % | B29: 0.1 | C29: ='Bidcell BOM (LTS)'!F386 -> 3.5242262 | D29: /Wp
A31: Scope of Work | C31: Remarks
A32: For Rooftop
A33: Access to the Roof | B33: Client Scope
A34: Gutter for cleaning/ Rain Water Harvesting | B34: Not Required
A35: Scope of mesh over the skylight | B35: Not Required
A36: Scope of Turbo vent | B36: Not Applicable
A37: Hand Railling | B37: 4PEL Scope
A38: Walkways materials | B38: FRP
A39: DC Cable Tray materials | B39: FRP
A40: AC Cable Tray materials (INV And ACCB panel) | B40: GI
A41: AC Cable Tray materials (ACCB And CLT panel) | B41: GI
...

Sheet Consumption analysis (BD)
B1: Fourth Partner Energy Pvt. Ltd | E1: DOC. No: 4PEL/DES-CA/555 #I01, R00.
E2: Issue Date: 11/12/2023.
E3: Control Copy No. 02.
B4: Consumption Analysis
A5: A) | B5: E Bill Parameters
B7: 0 | I7: =277 -> 277 | K7: 277
B8: Months | C8: Off Peak hrs (10 PM-05:30 AM) | D8: Normal hrs 05:30 AM-05:30 PM) | E8: Peak Hrs (TOU) (05:30 PM-10PM) | F8: Total Monthly consumption from DISCOM | G8: Generation at 277kWp | I8: Energy Per kWp (kWh) | J8: Capacity (kWP) as per day time consumption | L8: Difference of Consumption vs Generation (kWH) | M8: Banking Charges | O8: Note - 1. TOD zone will differ as per state regulatories norms, State DISCOM's 2.Yield will differ as per location & type of installation, module type. 3. Actual proposed size is based on shadow free area on roof/ground , state regulatories norms
B9: May'24 | G9: 30.74 | H9: =G9*93.18% -> 28.643532 | I9: =(H9/$I$7)*1000 -> 103.40625 | J9: =C9/I9 -> 0 | K9: =I9*$K$7 -> 28643.532 | L9: =C9-K9 -> -28643.532 | M9: =IF(L9<0, L9*1.5, 0) -> -42965.298
B10: April'24 | G10: 34.39 | H10: =G10*93.18% -> 32.044602 | I10: =(H10/$I$7)*1000 -> 115.68448 | J10: =C10/I10 -> 0 | K10: =I10*$K$7 -> 32044.602 | L10: =C10-K10 -> -32044.602 | M10: =IF(L10<0, L10*1.5, 0) -> -48066.903
G11: 29.89 | H11: =G11*93.18% -> 27.851502 | I11: =(H11/$I$7)*1000 -> 100.54694 | J11: =C11/I11 -> 0 | K11: =I11*$K$7 -> 27851.502 | L11: =C11-K11 -> -27851.502 | M11: =IF(L11<0, L11*1.5, 0) -> -41777.253
B12: Total | F12: =F9+F10 -> 0 | J12: =MIN(J11:J11) -> 0
B13: Considering Day time consumption only | E13: Considering Overall consumption | J13: =MIN(J12,J9:J10) -> 0
B14: Monthly Min Consumption | C14: =AVERAGE(D9:D10) -> #DIV/0! | E14: Monthly Avg Consumption | F14: =AVERAGE(F9:F11) -> #DIV/0! | H14: Minimum Capacity (kWP) considering 12 months
B15: 70% of Avergae Consumption to avoid Banking charges | C15: =C14*0.7 -> #DIV/0! | E15: Min offtake Guarantee to Discom (If any) | F15: 0 | H15: *March , April'2020 not considered due to COVID
B16: Net consumption available for offset by Solar | C16: =C15 -> #DIV/0! | E16: Net consumption available for offset by Solar | F16: =F14-F15 -> #DIV/0!
B17: Daily Avg Consumption | C17: =C16/30 -> #DIV/0! | E17: Daily Avg Consumption | F17: =F16/30 -> #DIV/0!
B18: Yield | E18: Yield
B19: SPP Size based on consumption (kWp) | C19: =C17/C18 -> #DIV/0! | E19: SPP Size based on consumption (kWp) | F19: =F17/F18 -> #DIV/0!
B21: Actual Proposed SPP size (kWp) | F21: 0
B22: % day time consumption replaced | D22: =D21*30*C18/C14 -> #DIV/0!
B23: % overall consumption replaced | D23: =D21*30*C18/F14 -> #DIV/0!
A25: B) | B25: Operational Parameters
B27: What is manufactured/Processed? Any heat / exhaust issues?
B28: Describe the load pattern? Constant/Seasonal/Order based
B29: Check the feasibility of obtaining 15 min load profile from client?
B30: No. of days per week plant is operational
B31: No. of shifts in which plant is operational
B32: Age of facility
B33: If ToD data not available, what is % day time consumption as per client input/experience
A36: C) | B36: Capacity assesment
B38: Parameters | C38: Maximum Installed Capacity (kWp) | D38: Remarks
B39: Based on G-Map | C39: 0
B40: Based on Consumption analysis
B41: Based on State regulatory norms (Net Metering or Min offtake commitment to Discom) | C41: 0
B43: Proposed Capacity | C43: 0
A46: D) | B46: Bill Analysis
B48: May'24 | F48: Billing Month
B49: Sanctioned Load/CD- 4950KVA | F49: March
B50: Particulars | C50: Units | D50: Rate | E50: Amount
B51: Total Charges | D51: =E51/C51 -> #DIV/0!
...

Sheet ESG (Design)
B1: INITIAL SITE SURVEY – ESG CHECKLIST | F1: DOC. No: 4PEL/DES-ISS/554 #I01, R00.
F2: Issue Date: 11/12/2023.
F3: Control Copy No.: 02.
A4: Name of Project Site | B4: Metro Junction mall
A5: Location/Address | B5: Metro Junction mall, Kalyan East | D5: State | F5: Maharashtra
A6: Country | B6: India
A7: Name of Surveyor | B7: Sagar Chavan | D7: Date | F7: 46153
A8: Department of Surveyor | B8: Design
A9: Name of Verifier
A10: Department of Verifier
A12: Aspects to check | C12: Yes | D12: No | E12: NA | F12: Remarks
A13: Key safety checks (evidence shall be provided against each significant check point with appropriate remark)
A14: Is suitable instrument available for taking actual measurements? | C14: yes
A15: Is any other technology other than manual measurement being used? (Ex. Drone etc.) | D15: No
A16: Is proper roof access available for roof? | C16: Yes
A17: If yes, what type of access is available, Monkey ladder, Step ladder or other? (Provide details in remark)
A18: If monkey ladder height is more than 10 meters, then is/are the rest platforms provided? | E18: NA
A19: (After every 10 meters there shall be minimum 10 meters gap between two platforms)
A20: Is ladder extended 1 meter above the roof? | E20: NA
A21: Is/are skylight(s) available on the roof? | E21: NA
A22: (If yes, please mention quantity and dimensions of the skylight)
A23: Is/are existing lifeline(s) available? | E23: NA
A24: If yes, please provide details. (Attach photographs)
A25: If 2 or more roofs are interconnected, is safe access available for roof-to-roof access? | E25: NA
A26: Please provide the access details.
A27: Is/are Turbo wind ventilator(s) available on roof? | E27: NA
A28: (If yes, please provide total numbers)
A29: Is alternative access available for the roof? | C29: Yes
A30: Has client provided Wire mesh below/above skylights for fall protection? | E30: NA
A31: If yes, does all the skylights on the roof are being covered?
A32: Is there any chemical / Hazardous waste emission on top of the roof? | D32: No
A33: Is there any Electric cables/ Pipes/Unprojected pipes routed on the roof? | C33: Yes
A34: Is lightning arrester available? If yes, does it cover all the roof area? | C34: Yes | F34: under exectuion, may not cover entire roof
A36: Are guard rails provided on the roof? | C36: Yes
A37: Are any measures of water harvesting provided on the roof? | C37: Yes
A38: Does client/off-taker has existing waste management policy?
A39: Is the client ready to provide material storage area during the development phase of plant? | C39: Yes
A40: Is any scrap yard available in client’s premises?
A41: Is the structural stability of the roof rust & prominent?
A42: Please mention: If any other Unsafe conditions observed on site | F42: out door ahu unit, piping & cable crossing etc

Sheet Input's from Site Visit
A1: Fourth Partner Energy Pvt. Ltd | F1: DOC. No: 4PEL/DES-ISS/110 #I01, R02.
F2: Issue Date: 11/12/2023.
F3: Control Copy No. 02.
A4: Inputs - Site Survey Form
A5: DETAILED PROJECT SITE SURVEY REPORT
A6: Client name | B6: ='Site Vist fomat (Design)'!B6 -> Metro Junction mall | E6: Power bills | F6: ='Input''s from BD(Sales)'!B81 -> Collected
A7: Client address | B7: ='Input''s from BD(Sales)'!B13 -> Metro Junction Mall, Kalyan - Shilphata Rd, Kalyan East, Kalyan, Maharashtra 421306 | E7: Contract demand * | F7: ='Site Vist fomat (Design)'!D18 -> 449 KVA
A8: Contact person name | B8: ='Site Vist fomat (Design)'!B7 -> 0 | E8: Incommer trans. rating* | F8: ='Site Vist fomat (Design)'!C19 -> Rating- kVA
A9: GPS Cordinates | B9: ='Site Vist fomat (Design)'!B9 -> 19.229564° N | E9: Netmetring voltage level | F9: ='Site Vist fomat (Design)'!B16 -> 0.45 kV | G9: Voltage level in kV | H9: =F9 -> 0.45 kV
A10: GPS Cordinates | B10: ='Site Vist fomat (Design)'!C9 -> 73.123271° E | E10: No. of Transformer | F10: ='Site Vist fomat (Design)'!B19 -> Qty - _01 Nos | G10: Voltage ratio | H10: ='Site Vist fomat (Design)'!D19 -> Voltage Ratio - ___/____
A11: Mob. No. | B11: ='Site Vist fomat (Design)'!E7 -> 0 | E11: Metering cubical (Class) | F11: ='Site Vist fomat (Design)'!B25 -> Class _____________
A12: Mail id | B12: ='Site Vist fomat (Design)'!G7 -> 0 | E12: ceig report | F12: ='Input''s from BD(Sales)'!B82 -> 0
A13: Proposed Kwp | B13: ='Site Vist fomat (Design)'!B15 -> kWp MwH | E13: Plant cad files | F13: ='Input''s from BD(Sales)'!B83 -> Available | J13: Locked Cell
A14: Project type | B14: ='Input''s from BD(Sales)'!B16 -> Capex | E14: plant SLD cad file | F14: ='Input''s from BD(Sales)'!B84 -> Available | J14: Editable cell
A15: Power Consumptions (Min.) | C15: Max. | E15: Hand sketch SLD | J15: *Mandatory
A16: APFC availability | C16: Solar termination | E16: No. of locations | F16: ='Input''s from BD(Sales)'!B18 -> 1 | G16: After Site Visit. | J16: Drop Down
A17: CT input for PFC | E17: Best Network operator | F17: <mention best oprator>
A18: ='Site Vist fomat (Design)'!C26 -> Metering CT& PT Details / Class | B18: ='Site Vist fomat (Design)'!D26 -> 0 | E18: Min & Max. Weather Temp.
A19: Plant Holiday/Power Holidays* | B19: ='Site Vist fomat (Design)'!B23 -> Days | E19: DG capacities * | F19: ='Site Vist fomat (Design)'!F23 -> Rating - _1010 kVA
A20: No. of service connection* | B20: ='Site Vist fomat (Design)'!B26 -> 2 | E20: No. of DGs * | F20: ='Site Vist fomat (Design)'!E23 -> Qty - __03 Nos
A21: PF maintaining | B21: ='Site Vist fomat (Design)'!G18 -> Power Factor: 0.89-0.995 | E21: Reverse Protections | F21: ='Site Vist fomat (Design)'!G24 -> (Yes/No)
A22: Any exsiting Plants | B22: Yes | C22: If yes | D22: ='Site Vist fomat (Design)'!B24 -> NO | E22: Metering class | F22: ='Site Vist fomat (Design)'!B25 -> Class _____________ | G22: rating, make ,model no. | H22: ='Site Vist fomat (Design)'!C25 -> Make: ___________________
A23: Plant details
B24: Plant 1 | C24: Plant 2 | D24: Plant 3 | E24: Plant 4 | F24: Plant 5 | G24: Plant 6 | H24: Plant 7 | I24: Plant 8 | J24: Plant 9 | K24: Plant 10 | L24: Plant 11 | M24: Plant 12 | N24: Plant 13 | O24: Plant 14 | P24: Plant 15
A25: Type of plant * | B25: Shed | C25: Shed | D25: Shed | E25: Shed | F25: Shed | G25: Shed | H25: Shed | I25: Shed | J25: Shed | K25: Shed | L25: Ground | M25: Ground | N25: Ground | O25: Ground | P25: Ground
A26: ='Site Vist fomat (Design)'!A27 -> Electrical Details
A27: ='Site Vist fomat (Design)'!A28 -> Name of the building (As per customer's nomenclature) | B27: ='Site Vist fomat (Design)'!B28 -> Main RCC B Block at LG | C27: ='Site Vist fomat (Design)'!C28 -> Main RCC D Block at LG | D27: ='Site Vist fomat (Design)'!D28 -> Parking | E27: ='Site Vist fomat (Design)'!E28 -> 0 | F27: ='Site Vist fomat (Design)'!F28 -> 0 | G27: ='Site Vist fomat (Design)'!G28 -> 0 | H27: ='Site Vist fomat (Design)'!H28 -> 0 | ... P27: ='Site Vist fomat (Design)'!P28 -> 0
A28: ='Site Vist fomat (Design)'!A31 -> Termination distance in mtrs | B28: ='Site Vist fomat (Design)'!B31 -> 170 | C28: ='Site Vist fomat (Design)'!C31 -> 220 | D28: ='Site Vist fomat (Design)'!D31 -> 200 | E28: ='Site Vist fomat (Design)'!E31 -> 0 | F28: ='Site Vist fomat (Design)'!F31 -> 0 | G28: ='Site Vist fomat (Design)'!G31 -> 0 | H28: ='Site Vist fomat (Design)'!H31 -> 0 | ... P28: ='Site Vist fomat (Design)'!P31 -> 0
A29: ='Site Vist fomat (Design)'!A32 -> Tentative location of inverter & LT Panel | B29: ='Site Vist fomat (Design)'!B32 -> at terrace level | C29: ='Site Vist fomat (Design)'!C32 -> at terrace level | D29: ='Site Vist fomat (Design)'!D32 -> At parking area | E29: ='Site Vist fomat (Design)'!E32 -> 0 | F29: ='Site Vist fomat (Design)'!F32 -> 0 | G29: ='Site Vist fomat (Design)'!G32 -> 0 | H29: ='Site Vist fomat (Design)'!H32 -> 0 | ... P29: ='Site Vist fomat (Design)'!P32 -> 0
A30: ='Site Vist fomat (Design)'!A33 -> Spare feeder avilability (mention as rating) | B30: ='Site Vist fomat (Design)'!B33 -> No | C30: ='Site Vist fomat (Design)'!C33 -> No | D30: ='Site Vist fomat (Design)'!D33 -> No | E30: ='Site Vist fomat (Design)'!E33 -> 0 | F30: ='Site Vist fomat (Design)'!F33 -> 0 | G30: ='Site Vist fomat (Design)'!G33 -> 0 | H30: ='Site Vist fomat (Design)'!H33 -> 0 | ... P30: ='Site Vist fomat (Design)'!P33 -> 0
A31: ='Site Vist fomat (Design)'!A34 -> Bus bar extensions required? Scope? | B31: ='Site Vist fomat (Design)'!B34 -> 0 | C31: ='Site Vist fomat (Design)'!C34 -> 0 | D31: ='Site Vist fomat (Design)'!D34 -> 0 | E31: ='Site Vist fomat (Design)'!E34 -> 0 | F31: ='Site Vist fomat (Design)'!F34 -> 0 | G31: ='Site Vist fomat (Design)'!G34 -> 0 | H31: ='Site Vist fomat (Design)'!H34 -> 0 | ... P31: ='Site Vist fomat (Design)'!P34 -> 0
A32: ='Site Vist fomat (Design)'!A35 -> Existing Bus Bar Size Material- Al/Cu./Type | B32: ='Site Vist fomat (Design)'!B35 -> 0 | C32: ='Site Vist fomat (Design)'!C35 -> 0 | D32: ='Site Vist fomat (Design)'!D35 -> 0 | E32: ='Site Vist fomat (Design)'!E35 -> 0 | F32: ='Site Vist fomat (Design)'!F35 -> 0 | G32: ='Site Vist fomat (Design)'!G35 -> 0 | H32: ='Site Vist fomat (Design)'!H35 -> 0 | ... P32: ='Site Vist fomat (Design)'!P35 -> 0
A33: ='Site Vist fomat (Design)'!A36 -> Main Incomer Rating | B33: ='Site Vist fomat (Design)'!B36 -> 0 | C33: ='Site Vist fomat (Design)'!C36 -> 0 | D33: ='Site Vist fomat (Design)'!D36 -> 0 | E33: ='Site Vist fomat (Design)'!E36 -> 0 | F33: ='Site Vist fomat (Design)'!F36 -> 0 | G33: ='Site Vist fomat (Design)'!G36 -> 0 | H33: ='Site Vist fomat (Design)'!H36 -> 0 | ... P33: ='Site Vist fomat (Design)'!P36 -> 0
A34: ='Site Vist fomat (Design)'!A37 -> Transmission method/ Method of Cable laying | B34: ='Site Vist fomat (Design)'!B37 -> 0 | C34: ='Site Vist fomat (Design)'!C37 -> 0 | D34: ='Site Vist fomat (Design)'!D37 -> 0 | E34: ='Site Vist fomat (Design)'!E37 -> 0 | F34: ='Site Vist fomat (Design)'!F37 -> 0 | G34: ='Site Vist fomat (Design)'!G37 -> 0 | H34: ='Site Vist fomat (Design)'!H37 -> 0 | ... P34: ='Site Vist fomat (Design)'!P37 -> 0
A35: ='Site Vist fomat (Design)'!A38 -> Termination LT Panel image | B35: ='Site Vist fomat (Design)'!B38 -> Attached | C35: ='Site Vist fomat (Design)'!C38 -> Attached | D35: ='Site Vist fomat (Design)'!D38 -> Attached | E35: ='Site Vist fomat (Design)'!E38 -> 0 | F35: ='Site Vist fomat (Design)'!F38 -> 0 | G35: ='Site Vist fomat (Design)'!G38 -> 0 | H35: ='Site Vist fomat (Design)'!H38 -> 0 | ... P35: ='Site Vist fomat (Design)'!P38 -> 0
A36: ='Site Vist fomat (Design)'!A39 -> Common Inputs
A37: ='Site Vist fomat (Design)'!A40 -> Distance from the sea shore? In Km | B37: ='Site Vist fomat (Design)'!B40 -> 40km | C37: ='Site Vist fomat (Design)'!C40 -> 40km | D37: ='Site Vist fomat (Design)'!D40 -> 40km | E37: ='Site Vist fomat (Design)'!E40 -> 0 | F37: ='Site Vist fomat (Design)'!F40 -> 0 | G37: ='Site Vist fomat (Design)'!G40 -> 0 | H37: ='Site Vist fomat (Design)'!H40 -> 0 | ... P37: ='Site Vist fomat (Design)'!P40 -> 0
A38: ='Site Vist fomat (Design)'!A41 -> Earth pit location identification | B38: ='Site Vist fomat (Design)'!B41 -> South (front side) | C38: ='Site Vist fomat (Design)'!C41 -> South (front side) | D38: ='Site Vist fomat (Design)'!D41 -> At parking area | E38: ='Site Vist fomat (Design)'!E41 -> 0 | F38: ='Site Vist fomat (Design)'!F41 -> 0 | G38: ='Site Vist fomat (Design)'!G41 -> 0 | H38: ='Site Vist fomat (Design)'!H41 -> 0 | ... P38: ='Site Vist fomat (Design)'!P41 -> 0
A39: ='Site Vist fomat (Design)'!A42 -> Availability of water system/Water tank for module cleaning | B39: ='Site Vist fomat (Design)'!B42 -> Available | C39: ='Site Vist fomat (Design)'!C42 -> Available | D39: ='Site Vist fomat (Design)'!D42 -> 0 | E39: ='Site Vist fomat (Design)'!E42 -> 0 | F39: ='Site Vist fomat (Design)'!F42 -> 0 | G39: ='Site Vist fomat (Design)'!G42 -> 0 | H39: ='Site Vist fomat (Design)'!H42 -> 0 | ... P39: ='Site Vist fomat (Design)'!P42 -> 0
A40: ='Site Vist fomat (Design)'!A43 -> Type of Water / Quality of water PPM (TDS Level) | B40: ='Site Vist fomat (Design)'!B43 -> 0 | C40: ='Site Vist fomat (Design)'!C43 -> 0 | D40: ='Site Vist fomat (Design)'!D43 -> 0 | E40: ='Site Vist fomat (Design)'!E43 -> 0 | F40: ='Site Vist fomat (Design)'!F43 -> 0 | G40: ='Site Vist fomat (Design)'!G43 -> 0 | H40: ='Site Vist fomat (Design)'!H43 -> 0 | ... P40: ='Site Vist fomat (Design)'!P43 -> 0
...

Sheet Site Vist fomat  (Design)
A1: Fourth Partner Energy Pvt. Ltd. | E1: DOC. No: | F1: 4PEL/DES-SSR/553 #I01, R00.
E2: Issue Date : | F2: 11/12/2023.
E3: Control Copy No : | F3: 2
A4: SITE SURVEY REPORT | E4: Survey Date : | F4: 46153
A5: General Information
A6: Name of the Customer | B6: Metro Junction mall
A7: Contact Person's Name & Designation | D7: Mobile No | F7: Email Id
A8: Site Address : | B8: Metro Junction Mall, Kalyan - Shilphata Rd, Kalyan East, Kalyan, Maharashtra 421306
A9: GPS Cordinates | B9: 19.229564° N | C9: 73.123271° E | D9: Nearest Railway Station | E9: Kalyan | F9: Nearest Highway | G9: Kalyan-Shil phata
A10: Industry Type | B10: Cement/Paint/FMCG/Metal/ITES/Auto & Auto Ancillary/Textile/Pharma/Plastic& Rubber/Infra/Telecom/Financial Srevices/Others (Specify) - Mall
A11: Type of business operation at site | B11: Manufacturing | C11: Warehousing | D11: Packaging | E11: Retail | F11: Service | G11: Others (Specify) - Mall
A12: Type of Installation | C12: RCC | E12: Parking
A13: Ownership | B13: Owned | C13: Leased | D13: Lease expiry after yrs | E13: Right to Install SPP --> | F13: Yes | G13: No
A14: Customer RE Requirement
A15: Expected Solar PV / Storage Capacity | B15: kWp MwH | C15: CT | D15: Gross Metering | E15: Captive | F15: On Grid | G15: Off Grid
A16: Proposed SPP Evacuation Voltage | B16: 0.45 kV | C16: (If Evacuation Voltage >=11 KV, check space available to construct substation)
A17: Existing Electrical Infrastructure
A18: Discom Name | B18: MSEDCL | C18: Contract Demand | D18: 449 KVA | E18: Total Connected Load | F18: kW | G18: Power Factor: 0.89-0.995
A19: Distribution Transformer (DT) Details | B19: Qty - _01 Nos | C19: Rating- kVA | D19: Voltage Ratio - ___/____ | E19: Vector Group- _______ | F19: Shortcircuit Level (HT VCB Level) - _______ Kv | G19: Make & Model for each transformer -
A20: Sources of Power Available for synchronizing | B20: EB Supply | C20: DG Supply | D20: CPP | E20: Others (specify) | F20: Synchronisation | G20: Manual/Automatic - Automatic
A21: Grid Outage Data | B21: No. of Hours/day :__________ | C21: Operational Days in a Year | D21: Days | E21: Grid Frequency/Voltage Fluctuations (Yes/No) | F21: Yes | G21: No
B22: No. of times/Day: ______________ | C22: No of Off Days for Maintenance & Load | D22: Days | E22: kW | F22: Operational Hours in a Day: ________ | G22: No of Shifts/Day: __________
A23: No of Off Days for Holidays & Load | B23: Days | C23: kW | D23: Installed DG Set | E23: Qty - __03 Nos | F23: Rating - _1010 kVA | G23: Voltage _400 V
A24: Existing Solar Capacity in KWp (DC capacity) | B24: NO | C24: 0 | D24: Is the existing plant Net Metered? | E24: (Yes/No) | F24: Is the existing plant installed with RPR? | G24: (Yes/No)
A25: EB Meter Details | B25: Class _____________ | C25: Make: ___________________ | D25: STC Rating ____________ | E25: APFC Panel (Location & Rating) type( automatice/manual)
A26: No. of service connection (Qty.) | B26: 2 | C26: Metering CT& PT Details / Class | E26: Earth resistivity & Standards/Specifications | F26: 2 ohm- convetional type/ chemical
A27: Electrical Details | H27: Electrical Details
A28: Name of the building (As per customer's nomenclature) | B28: Main RCC B Block at LG | C28: Main RCC D Block at LG | D28: Parking
A29: Location wise Exisiting LT panel breker capacity | B29: LT Room B Block at LG Main termination is in Ground floor | C29: LT Room D Block at LG Main termination is in Ground floor | D29: LT Room B Block at LG Main termination is in Ground floor
A30: Incomer Cable runs and size
A31: Termination distance in mtrs | B31: 170 | C31: 220 | D31: 200
A32: Tentative location of inverter & LT Panel | B32: at terrace level | C32: at terrace level | D32: At parking area
A33: Spare feeder avilability (mention as rating) | B33: No | C33: No | D33: No
A34: Bus bar extensions required? Scope?
A35: Existing Bus Bar Size Material- Al/Cu./Type
A36: Main Incomer Rating
A37: Transmission method/ Method of Cable laying
A38: Termination LT Panel image | B38: Attached | C38: Attached | D38: Attached
A39: Common Inputs | H39: Commen inputs
A40: Distance from the sea shore? In Km | B40: 40km | C40: 40km | D40: 40km
...

Sheet Input's from Initial Design
C1: Fourth Partner Energy Pvt. Ltd | Q1: DOC. No: 4PEL/DES-IDS/039 #I01, R05.
Q2: Issue Date: 23/02/2026.
Q3: Control Copy No. 02.
C4: Initial Design Sheet
A5: DETAILED INITIAL DESIGN REPORT | L5: =IF(OR('Site Vist fomat (Design)'!B24=0,'Site Vist fomat (Design)'!C24=0),"Please fill Existing Plant details","") -> Please fill Existing Plant details | M5: Inputs for initial design from BD | R5: Information Sheet (String Inv. LT)
A6: Availability of RFP/RFQ | C6: =IF('Input''s from BD(Sales)'!B15="", "Not Updated", IFERROR('Input''s from BD(Sales)'!B15, "Not Updated")) -> Yes | F6: Is Design prepared According to RFP/RFQ | I6: Yes | M6: Module wattage (Wp) | O6: ='Input''s from BD(Sales)'!B20 -> 595 / 590 / 585
A7: Site Name & State | C7: ='Input''s from Site Visit'!B6 -> Metro Junction mall | F7: ='Input''s from BD(Sales)'!B10 -> Maharashtra | I7: Comment | M7: Module Origin | O7: ='Input''s from BD(Sales)'!B21 -> ALMM Approved | R7: Shed | S7: =IF($C$25=R7,$G$25,0)+IF($C$26=R7,$G$26,0)+IF($C$27=R7,$G$27,0)+IF($C$28=R7,$G$28,0)+IF($C$29=R7,$G$29)+IF($C$30=R7,$G$30,0)+IF($C$31=R7,$G$31,0)+IF($C$32=R7,$G$32,0)+IF($C$33=R7,$G$33,0)+IF($C$34=R7,$G$34)+IF($C$35=R7,$G$35,0)+IF($C$36=R7,$G$36,0)+IF($C$37=R7,$G$37,0)+IF($C$38=R7,$G$38,0)+IF($C$39=R7,$G$39,0)+IF($C$40=R7,$G$40,0)+IF($C$41=R7,$G$41,0)+IF($C$42=R7,$G$42,0)+IF($C$43=R7,$G$43,0)+IF($C$44=R7,$G$44,0)+IF($C$45=R7,$G$45,0)+IF($C$46=R7,$G$46,0)+IF($C$47=R7,$G$47,0)+IF($C$48=R7,$G$48,0)+IF($C$49=R7,$G$49,0)+IF($C$50=R7,$G$50,0)+IF($C$51=R7,$G$51,0)+IF($C$52=R7,$G$52,0)+IF($C$53=R7,$G$53,0)+IF($C$54=R7,$G$54,0) -> 0
A8: Address & Lat Long | C8: ='Input''s from Site Visit'!B7 -> Metro Junction Mall, Kalyan - Shilphata Rd, Kalyan East, Kalyan, Maharashtra 421306 | F8: ='Input''s from BD(Sales)'!B14 -> 19°13'45.98"N 73°07'23.94"E | M8: Prefered Inverter make | O8: ='Input''s from BD(Sales)'!B22 -> Solis / Sungrow / Equivalent | R8: Long Rail | S8: =IF($C$25=R8,$G$25,0)+IF($C$26=R8,$G$26,0)+IF($C$27=R8,$G$27,0)+IF($C$28=R8,$G$28,0)+IF($C$29=R8,$G$29)+IF($C$30=R8,$G$30,0)+IF($C$31=R8,$G$31,0)+IF($C$32=R8,$G$32,0)+IF($C$33=R8,$G$33,0)+IF($C$34=R8,$G$34)+IF($C$35=R8,$G$35,0)+IF($C$36=R8,$G$36,0)+IF($C$37=R8,$G$37,0)+IF($C$38=R8,$G$38,0)+IF($C$39=R8,$G$39,0)+IF($C$40=R8,$G$40,0)+IF($C$41=R8,$G$41,0)+IF($C$42=R8,$G$42,0)+IF($C$43=R8,$G$43,0)+IF($C$44=R8,$G$44,0)+IF($C$45=R8,$G$45,0)+IF($C$46=R8,$G$46,0)+IF($C$47=R8,$G$47,0)+IF($C$48=R8,$G$48,0)+IF($C$49=R8,$G$49,0)+IF($C$50=R8,$G$50,0)+IF($C$51=R8,$G$51,0)+IF($C$52=R8,$G$52,0)+IF($C$53=R8,$G$53,0)+IF($C$54=R8,$G$54,0) -> 0
A9: Approval Details | C9: Name of the Person | F9: Approval Date | M9: DC/AC Ratio | O9: ='Input''s from BD(Sales)'!B23 -> 0 | R9: RCC | S9: =IF($C$25=R9,$G$25,0)+IF($C$26=R9,$G$26,0)+IF($C$27=R9,$G$27,0)+IF($C$28=R9,$G$28,0)+IF($C$29=R9,$G$29)+IF($C$30=R9,$G$30,0)+IF($C$31=R9,$G$31,0)+IF($C$32=R9,$G$32,0)+IF($C$33=R9,$G$33,0)+IF($C$34=R9,$G$34)+IF($C$35=R9,$G$35,0)+IF($C$36=R9,$G$36,0)+IF($C$37=R9,$G$37,0)+IF($C$38=R9,$G$38,0)+IF($C$39=R9,$G$39,0)+IF($C$40=R9,$G$40,0)+IF($C$41=R9,$G$41,0)+IF($C$42=R9,$G$42,0)+IF($C$43=R9,$G$43,0)+IF($C$44=R9,$G$44,0)+IF($C$45=R9,$G$45,0)+IF($C$46=R9,$G$46,0)+IF($C$47=R9,$G$47,0)+IF($C$48=R9,$G$48,0)+IF($C$49=R9,$G$49,0)+IF($C$50=R9,$G$50,0)+IF($C$51=R9,$G$51,0)+IF($C$52=R9,$G$52,0)+IF($C$53=R9,$G$53,0)+IF($C$54=R9,$G$54,0) -> 0
A10: Initial Design Done By | C10: Ashish A | F10: Date: | G10: 46199 | M10: Roof Puncturing permission from client | R10: RCC Raised | S10: =IF($C$25=R10,$G$25,0)+IF($C$26=R10,$G$26,0)+IF($C$27=R10,$G$27,0)+IF($C$28=R10,$G$28,0)+IF($C$29=R10,$G$29)+IF($C$30=R10,$G$30,0)+IF($C$31=R10,$G$31,0)+IF($C$32=R10,$G$32,0)+IF($C$33=R10,$G$33,0)+IF($C$34=R10,$G$34)+IF($C$35=R10,$G$35,0)+IF($C$36=R10,$G$36,0)+IF($C$37=R10,$G$37,0)+IF($C$38=R10,$G$38,0)+IF($C$39=R10,$G$39,0)+IF($C$40=R10,$G$40,0)+IF($C$41=R10,$G$41,0)+IF($C$42=R10,$G$42,0)+IF($C$43=R10,$G$43,0)+IF($C$44=R10,$G$44,0)+IF($C$45=R10,$G$45,0)+IF($C$46=R10,$G$46,0)+IF($C$47=R10,$G$47,0)+IF($C$48=R10,$G$48,0)+IF($C$49=R10,$G$49,0)+IF($C$50=R10,$G$50,0)+IF($C$51=R10,$G$51,0)+IF($C$52=R10,$G$52,0)+IF($C$53=R10,$G$53,0)+IF($C$54=R10,$G$54,0) -> 400.52
A11: Initial Design Approved By | C11: Sagar C | G11: 46199 | M11: ='Input''s from BD(Sales)'!A43 -> Modules (MMS) | O11: ='Input''s from BD(Sales)'!B43 -> 0 | R11: RCC Raised on Pillars | S11: =IF($C$25=R11,$G$25,0)+IF($C$26=R11,$G$26,0)+IF($C$27=R11,$G$27,0)+IF($C$28=R11,$G$28,0)+IF($C$29=R11,$G$29)+IF($C$30=R11,$G$30,0)+IF($C$31=R11,$G$31,0)+IF($C$32=R11,$G$32,0)+IF($C$33=R11,$G$33,0)+IF($C$34=R11,$G$34)+IF($C$35=R11,$G$35,0)+IF($C$36=R11,$G$36,0)+IF($C$37=R11,$G$37,0)+IF($C$38=R11,$G$38,0)+IF($C$39=R11,$G$39,0)+IF($C$40=R11,$G$40,0)+IF($C$41=R11,$G$41,0)+IF($C$42=R11,$G$42,0)+IF($C$43=R11,$G$43,0)+IF($C$44=R11,$G$44,0)+IF($C$45=R11,$G$45,0)+IF($C$46=R11,$G$46,0)+IF($C$47=R11,$G$47,0)+IF($C$48=R11,$G$48,0)+IF($C$49=R11,$G$49,0)+IF($C$50=R11,$G$50,0)+IF($C$51=R11,$G$51,0)+IF($C$52=R11,$G$52,0)+IF($C$53=R11,$G$53,0)+IF($C$54=R11,$G$54,0) -> 0
I12: =IF(I6=0,"Please fill RFQ/RFP details","") | M12: ='Input''s from BD(Sales)'!A45 -> Lifeline location | O12: ='Input''s from BD(Sales)'!B45 -> 0 | R12: Ground Mounted | S12: =IF($C$25=R12,$G$25,0)+IF($C$26=R12,$G$26,0)+IF($C$27=R12,$G$27,0)+IF($C$28=R12,$G$28,0)+IF($C$29=R12,$G$29)+IF($C$30=R12,$G$30,0)+IF($C$31=R12,$G$31,0)+IF($C$32=R12,$G$32,0)+IF($C$33=R12,$G$33,0)+IF($C$34=R12,$G$34)+IF($C$35=R12,$G$35,0)+IF($C$36=R12,$G$36,0)+IF($C$37=R12,$G$37,0)+IF($C$38=R12,$G$38,0)+IF($C$39=R12,$G$39,0)+IF($C$40=R12,$G$40,0)+IF($C$41=R12,$G$41,0)+IF($C$42=R12,$G$42,0)+IF($C$43=R12,$G$43,0)+IF($C$44=R12,$G$44,0)+IF($C$45=R12,$G$45,0)+IF($C$46=R12,$G$46,0)+IF($C$47=R12,$G$47,0)+IF($C$48=R12,$G$48,0)+IF($C$49=R12,$G$49,0)+IF($C$50=R12,$G$50,0)+IF($C$51=R12,$G$51,0)+IF($C$52=R12,$G$52,0)+IF($C$53=R12,$G$53,0)+IF($C$54=R12,$G$54,0) -> 0
A13: Revision No. | C13: DR1 * | D13: DR2 * | E13: DR3 * | F13: DR4 * | G13: DR5 * | H13: DR6 * | I13: Notes for Design from BD | M13: Walkway Dimension (W) | O13: ='Input''s from BD(Sales)'!B44 -> 0 | R13: Parking- Car/Bike | S13: =IF($C$25=R13,$G$25,0)+IF($C$26=R13,$G$26,0)+IF($C$27=R13,$G$27,0)+IF($C$28=R13,$G$28,0)+IF($C$29=R13,$G$29)+IF($C$30=R13,$G$30,0)+IF($C$31=R13,$G$31,0)+IF($C$32=R13,$G$32,0)+IF($C$33=R13,$G$33,0)+IF($C$34=R13,$G$34)+IF($C$35=R13,$G$35,0)+IF($C$36=R13,$G$36,0)+IF($C$37=R13,$G$37,0)+IF($C$38=R13,$G$38,0)+IF($C$39=R13,$G$39,0)+IF($C$40=R13,$G$40,0)+IF($C$41=R13,$G$41,0)+IF($C$42=R13,$G$42,0)+IF($C$43=R13,$G$43,0)+IF($C$44=R13,$G$44,0)+IF($C$45=R13,$G$45,0)+IF($C$46=R13,$G$46,0)+IF($C$47=R13,$G$47,0)+IF($C$48=R13,$G$48,0)+IF($C$49=R13,$G$49,0)+IF($C$50=R13,$G$50,0)+IF($C$51=R13,$G$51,0)+IF($C$52=R13,$G$52,0)+IF($C$53=R13,$G$53,0)+IF($C$54=R13,$G$54,0) -> 0
A14: Receive date | C14: 46163 | D14: 46177 | E14: 46199 | I14: ='Input''s from BD(Sales)'!A91 -> 0 | M14: Anchoring permission for RCC | O14: ='Input''s from BD(Sales)'!B46 -> 0 | R14: Parking-Truck/Bus | S14: =IF($C$25=R14,$G$25,0)+IF($C$26=R14,$G$26,0)+IF($C$27=R14,$G$27,0)+IF($C$28=R14,$G$28,0)+IF($C$29=R14,$G$29)+IF($C$30=R14,$G$30,0)+IF($C$31=R14,$G$31,0)+IF($C$32=R14,$G$32,0)+IF($C$33=R14,$G$33,0)+IF($C$34=R14,$G$34)+IF($C$35=R14,$G$35,0)+IF($C$36=R14,$G$36,0)+IF($C$37=R14,$G$37,0)+IF($C$38=R14,$G$38,0)+IF($C$39=R14,$G$39,0)+IF($C$40=R14,$G$40,0)+IF($C$41=R14,$G$41,0)+IF($C$42=R14,$G$42,0)+IF($C$43=R14,$G$43,0)+IF($C$44=R14,$G$44,0)+IF($C$45=R14,$G$45,0)+IF($C$46=R14,$G$46,0)+IF($C$47=R14,$G$47,0)+IF($C$48=R14,$G$48,0)+IF($C$49=R14,$G$49,0)+IF($C$50=R14,$G$50,0)+IF($C$51=R14,$G$51,0)+IF($C$52=R14,$G$52,0)+IF($C$53=R14,$G$53,0)+IF($C$54=R14,$G$54,0) -> 0
A15: Reason for Revision | C15: Initial Design | D15: Capacity increased | E15: AS per client reuirement layout revised | M15: PV Syst | O15: ='Input''s from BD(Sales)'!B47 -> 0 | R15: Floating | S15: =IF($C$25=R15,$G$25,0)+IF($C$26=R15,$G$26,0)+IF($C$27=R15,$G$27,0)+IF($C$28=R15,$G$28,0)+IF($C$29=R15,$G$29)+IF($C$30=R15,$G$30,0)+IF($C$31=R15,$G$31,0)+IF($C$32=R15,$G$32,0)+IF($C$33=R15,$G$33,0)+IF($C$34=R15,$G$34)+IF($C$35=R15,$G$35,0)+IF($C$36=R15,$G$36,0)+IF($C$37=R15,$G$37,0)+IF($C$38=R15,$G$38,0)+IF($C$39=R15,$G$39,0)+IF($C$40=R15,$G$40,0)+IF($C$41=R15,$G$41,0)+IF($C$42=R15,$G$42,0)+IF($C$43=R15,$G$43,0)+IF($C$44=R15,$G$44,0)+IF($C$45=R15,$G$45,0)+IF($C$46=R15,$G$46,0)+IF($C$47=R15,$G$47,0)+IF($C$48=R15,$G$48,0)+IF($C$49=R15,$G$49,0)+IF($C$50=R15,$G$50,0)+IF($C$51=R15,$G$51,0)+IF($C$52=R15,$G$52,0)+IF($C$53=R15,$G$53,0)+IF($C$54=R15,$G$54,0) -> 0
R16: Total Capacity | S16: =SUM(S8:S15) -> 400.52
A17: Date of Sent | C17: 46164 | D17: 46177 | E17: 46199
S19: Inverter Over loading indication | V19: NIL | W19: 0 to 1 | X19: 1 to 1.25
D20: =IF('Site Vist fomat (Design)'!B26=0,"Please fill number of service connections in Site Visit sheet","") | V20: 1.25-1.4 | W20: 1.4-1.45 | X20: Above 1.45
A21: String Inverter Initial Design | D21: Module Make & Origin | F21: Renewsys | G21: Indian ALMM | H21: =IF(F21=0,"Please fill Module Wp details","") | K21: =IF(G21=0,"Please fill Module Make details","") | L21: Select the Optimazer Model for Solar edge inverter | O21: Optimizers- Model-S 1400/ S 1500 | S21: Module Tilt | V21: < 5 | W21: < 8 | X21: > 8 | Z21: Click to check the Earth strip selection | AG21: =IF('Input''s from BD(Sales)'!B10='Input''s from BD(Sales)'!A298,"Consider Conventional LA for Tamilnadu"," ") | AJ21: =IF(OR('Input''s from BD(Sales)'!B10='Input''s from BD(Sales)'!A282,'Input''s from BD(Sales)'!B10='Input''s from BD(Sales)'!A298),"Railings are mandate for Tamilnadu/Haryana","Consider Railings for Module tilt >=8") -> Consider Railings for Module tilt >=8
D22: Module Wattage | F22: 620 | G22: Wp
A23: Sl.No | B23: Building/Location Name | C23: Type of Installation | D23: Type of sheet | E23: Available Modules | F23: No. of Modules Utilized | G23: DC Capacity in kWp | H23: Solis | R23: AC Capacity in kW | S23: Inverter Overloading DC/AC Ratio | V23: Common item for Rooftop and Ground mounted | AP23: For Rooftop site's | BB23: For Ground Mounted Site's
H24: =IF($H$23=$D$512,F512,IF($H$23=$D$514,F514,IF($H$23=$D$516,F516,IF($H$23=$D$518,F518,IF($H$23=$D$520,F520,IF($H$23=$D$522,F522,IF($H$23=$D$524,F524,IF($H$23=$D$526,F526,IF($H$23=$D$528,F528,IF($H$23=$D$530,F530,IF($H$23=$D$532,F532,IF($H$23=$D$534,F534,IF($H$23=$D$536,F536,""))))))))))))) -> 150 | I24: =IF($H$23=$D$512,G512,IF($H$23=$D$514,G514,IF($H$23=$D$516,G516,IF($H$23=$D$518,G518,IF($H$23=$D$520,G520,IF($H$23=$D$522,G522,IF($H$23=$D$524,G524,IF($H$23=$D$526,G526,IF($H$23=$D$528,G528,IF($H$23=$D$530,G530,IF($H$23=$D$532,G532,IF($H$23=$D$534,G534,IF($H$23=$D$536,G536,""))))))))))))) -> 125 | J24: =IF($H$23=$D$512,H512,IF($H$23=$D$514,H514,IF($H$23=$D$516,H516,IF($H$23=$D$518,H518,IF($H$23=$D$520,H520,IF($H$23=$D$522,H522,IF($H$23=$D$524,H524,IF($H$23=$D$526,H526,IF($H$23=$D$528,H528,IF($H$23=$D$530,H530,IF($H$23=$D$532,H532,IF($H$23=$D$534,H534,IF($H$23=$D$536,H536,""))))))))))))) -> 80 | K24: =IF($H$23=$D$512,I512,IF($H$23=$D$514,I514,IF($H$23=$D$516,I516,IF($H$23=$D$518,I518,IF($H$23=$D$520,I520,IF($H$23=$D$522,I522,IF($H$23=$D$524,I524,IF($H$23=$D$526,I526,IF($H$23=$D$528,I528,IF($H$23=$D$530,I530,IF($H$23=$D$532,I532,IF($H$23=$D$534,I534,IF($H$23=$D$536,I536,""))))))))))))) -> 60 | L24: =IF($H$23=$D$512,J512,IF($H$23=$D$514,J514,IF($H$23=$D$516,J516,IF($H$23=$D$518,J518,IF($H$23=$D$520,J520,IF($H$23=$D$522,J522,IF($H$23=$D$524,J524,IF($H$23=$D$526,J526,IF($H$23=$D$528,J528,IF($H$23=$D$530,J530,IF($H$23=$D$532,J532,IF($H$23=$D$534,J534,IF($H$23=$D$536,J536,""))))))))))))) -> 50 | M24: =IF($H$23=$D$512,K512,IF($H$23=$D$514,K514,IF($H$23=$D$516,K516,IF($H$23=$D$518,K518,IF($H$23=$D$520,K520,IF($H$23=$D$522,K522,IF($H$23=$D$524,K524,IF($H$23=$D$526,K526,IF($H$23=$D$528,K528,IF($H$23=$D$530,K530,IF($H$23=$D$532,K532,IF($H$23=$D$534,K534,IF($H$23=$D$536,K536,""))))))))))))) -> 30 | N24: =IF($H$23=$D$512,L512,IF($H$23=$D$514,L514,IF($H$23=$D$516,L516,IF($H$23=$D$518,L518,IF($H$23=$D$520,L520,IF($H$23=$D$522,L522,IF($H$23=$D$524,L524,IF($H$23=$D$526,L526,IF($H$23=$D$528,L528,IF($H$23=$D$530,L530,IF($H$23=$D$532,L532,IF($H$23=$D$534,L534,IF($H$23=$D$536,L536,""))))))))))))) -> 25 | O24: =IF($H$23=$D$512,M512,IF($H$23=$D$514,M514,IF($H$23=$D$516,M516,IF($H$23=$D$518,M518,IF($H$23=$D$520,M520,IF($H$23=$D$522,M522,IF($H$23=$D$524,M524,IF($H$23=$D$526,M526,IF($H$23=$D$528,M528,IF($H$23=$D$530,M530,IF($H$23=$D$532,M532,IF($H$23=$D$534,M534,IF($H$23=$D$536,M536,""))))))))))))) -> 20 | ... Q24: =IF($H$23=$D$512,O512,IF($H$23=$D$514,O514,IF($H$23=$D$516,O516,IF($H$23=$D$518,O518,IF($H$23=$D$520,O520,IF($H$23=$D$522,O522,IF($H$23=$D$524,O524,IF($H$23=$D$526,O526,IF($H$23=$D$528,O528,IF($H$23=$D$530,O530,IF($H$23=$D$532,O532,IF($H$23=$D$534,O534,IF($H$23=$D$536,O536,""))))))))))))) -> 10 | V24: Total No. of strings | W24: Module Tilt in Degree | X24: Structure clearance in mm | Y24: Earth strip Length in Mtrs (MMS) | Z24: Earth strip size (MMS) | AA24: Earth strip Length in Mtrs (INV) | AB24: Earth strip size (INV) | AC24: Earth strip Length in Mtrs (ACCB PANEL) | AD24: Earth strip size (ACCB PANEL) | AE24: Earth strip Length in Mtrs (LA) | AF24: Earth strip size (LA) | AG24: Type of Lightening Arrestor | AH24: No. of LA's (Qty.) | AI24: Water pipe line in Mtrs | AJ24: Walkway in Mtrs | AK24: Railings in Mtrs | AL24: Lifeline Rope in Rmtrs | AM24: No. of Lifeline Post (Qty.) | AN24: DC Cable Length in Mtrs 4 Sqmm | AO24: DC Cable Length in Mtrs 6 Sqmm | AP24: DC cable tray length in Mtrs 50x50x2mm | AQ24: DC cable tray length in Mtrs 100x50x2mm | AR24: Zero Degree Walkways in Mtrs | AS24: Step Walkway in Mtrs | AT24: Gutter length for harvesting in Mtrs | AU24: Skylight Width in mm | AV24: Skylight Length in Run. Mtrs | AW24: Turbo Vent Qty. | AX24: Roof monitor cross over (Qty.) | AY24: Ladder for Roof to roof Height in Mtrs | AZ24: Type of Ladder | BA24: Building Height in Mtrs | BB24: Total Plant Area in Acrs | BC24: DWC pipe for DC cable in Mtrs | BD24: Approach Road in Mtrs | BE24: Internal Road in Mtrs | BF24: Strom Water Drainage in Mtrs | BG24: Peripheral Length in Mtrs | BH24: Peripheral Road in Mtrs
A25: 1 | B25: Main RCC B Block at LG South side | C25: RCC Raised | E25: =(3*15+2*12)*2+(254*2) -> 646 | F25: =((21*4+3*18)+(9*19+5*21)+(8*19+4*20)) -> 646 | G25: =IF(C25<>0,F25*$F$22/1000,0) -> 400.52 | H25: 2 | R25: =IF(F25<>0,H25*$H$24+I25*$I$24+J25*$J$24+K25*$K$24+L25*$L$24+$M$24*M25+N25*$N$24+$O$24*O25+$P$24*P25+$Q$24*Q25,0) -> 300 | S25: =G25/R25 -> 1.3350667 | V25: 33 | W25: 5 | X25: =_xlfn.XLOOKUP(C25,$O$124:$O$132,$P$124:$P$132," ") -> 3000 mm | Y25: =(18*2+30+40)+(50*2+70+80)+((17*2)*4)*2+16*2+40*2-100 -> 640 | Z25: 25x3mm | AA25: =(50+25+15+16+40)*2+(2*5*2)-50 -> 262 | AB25: 25x3mm | AC25: =(20+16+25)*2 -> 122 | AD25: 25x3mm | AE25: =(5+20+35)*2 -> 120 | AF25: 25x6mm | AG25: ESE 107 Mtrs Radius | AH25: 1 | AI25: =(25+18+15+4)+(40+10+20)+(80+40+18+15*2+45*2+4*2)+(60)-50 -> 408 | AJ25: =(40*2+15*2+45*2+18+65)+(22*2+18+30)-25 -> 350 | AK25: 0 | AL25: =(40*2+15*2+45*2+18+65)+(22*2+18+30)-25 -> 350 | AM25: =(5*2+3*2+6*2+3+8)+(3*2+3+4)-1 -> 51 | AN25: =33*60*2*1.1-306 -> 4050 | AO25: 0 | AP25: =(40+15+15+40)*2+(40+25)*2 -> 350 | AQ25: 0 | BA25: =IF(OR(C25=R$7,C25=R$8,C25=R$9,C25=R$10,C25=R$11),'Site Vist fomat (Design)'!B$64,0) -> 0 | BF25: =BE25*2 -> 0
A26: =A25+1 -> 2 | B26: LT Panel - 2 | G26: =IF(C26<>0,F26*$F$22/1000,0) -> 0 | R26: =IF(F26<>0,H26*$H$24+I26*$I$24+J26*$J$24+K26*$K$24+L26*$L$24+$M$24*M26+N26*$N$24+$O$24*O26+$P$24*P26+$Q$24*Q26,0) -> 0 | S26: =G26/R26 -> #DIV/0! | X26: =_xlfn.XLOOKUP(C26,$O$124:$O$132,$P$124:$P$132," ") | BA26: =IF(OR(C26=R$7,C26=R$8,C26=R$9,C26=R$10,C26=R$11),'Site Vist fomat (Design)'!C$64,0) -> 0 | BF26: =BE26*2 -> 0
A27: =A26+1 -> 3 | G27: =IF(C27<>0,F27*$F$22/1000,0) -> 0 | R27: =IF(F27<>0,H27*$H$24+I27*$I$24+J27*$J$24+K27*$K$24+L27*$L$24+$M$24*M27+N27*$N$24+$O$24*O27+$P$24*P27+$Q$24*Q27,0) -> 0 | S27: =G27/R27 -> #DIV/0! | X27: =_xlfn.XLOOKUP(C27,$O$124:$O$132,$P$124:$P$132," ") | BA27: =IF(OR(C27=R$7,C27=R$8,C27=R$9,C27=R$10,C27=R$11),'Site Vist fomat (Design)'!D$64,0) -> 0 | BF27: =BE27*2 -> 0
A28: =A27+1 -> 4 | G28: =IF(C28<>0,F28*$F$22/1000,0) -> 0 | R28: =IF(F28<>0,H28*$H$24+I28*$I$24+J28*$J$24+K28*$K$24+L28*$L$24+$M$24*M28+N28*$N$24+$O$24*O28+$P$24*P28+$Q$24*Q28,0) -> 0 | S28: =G28/R28 -> #DIV/0! | X28: =_xlfn.XLOOKUP(C28,$O$124:$O$132,$P$124:$P$132," ") | BA28: =IF(OR(C28=R$7,C28=R$8,C28=R$9,C28=R$10,C28=R$11),'Site Vist fomat (Design)'!E$64,0) -> 0 | BF28: =BE28*2 -> 0
A29: =A28+1 -> 5 | G29: =IF(C29<>0,F29*$F$22/1000,0) -> 0 | R29: =IF(F29<>0,H29*$H$24+I29*$I$24+J29*$J$24+K29*$K$24+L29*$L$24+$M$24*M29+N29*$N$24+$O$24*O29+$P$24*P29+$Q$24*Q29,0) -> 0 | S29: =G29/R29 -> #DIV/0! | X29: =_xlfn.XLOOKUP(C29,$O$124:$O$132,$P$124:$P$132," ") | BA29: =IF(OR(C29=R$7,C29=R$8,C29=R$9,C29=R$10,C29=R$11),'Site Vist fomat (Design)'!F$64,0) -> 0 | BF29: =BE29*2 -> 0
A30: =A29+1 -> 6 | G30: =IF(C30<>0,F30*$F$22/1000,0) -> 0 | R30: =IF(F30<>0,H30*$H$24+I30*$I$24+J30*$J$24+K30*$K$24+L30*$L$24+$M$24*M30+N30*$N$24+$O$24*O30+$P$24*P30+$Q$24*Q30,0) -> 0 | S30: =G30/R30 -> #DIV/0! | X30: =_xlfn.XLOOKUP(C30,$O$124:$O$132,$P$124:$P$132," ") | BA30: =IF(OR(C30=R$7,C30=R$8,C30=R$9,C30=R$10,C30=R$11),'Site Vist fomat (Design)'!G$64,0) -> 0 | BF30: =BE30*2 -> 0
A31: =A30+1 -> 7 | G31: =IF(C31<>0,F31*$F$22/1000,0) -> 0 | R31: =IF(F31<>0,H31*$H$24+I31*$I$24+J31*$J$24+K31*$K$24+L31*$L$24+$M$24*M31+N31*$N$24+$O$24*O31+$P$24*P31+$Q$24*Q31,0) -> 0 | S31: =G31/R31 -> #DIV/0! | X31: =_xlfn.XLOOKUP(C31,$O$124:$O$132,$P$124:$P$132," ") | BA31: =IF(OR(C31=R$7,C31=R$8,C31=R$9,C31=R$10,C31=R$11),'Site Vist fomat (Design)'!H$64,0) -> 0 | BF31: =BE31*2 -> 0
A32: =A31+1 -> 8 | G32: =IF(C32<>0,F32*$F$22/1000,0) -> 0 | R32: =IF(F32<>0,H32*$H$24+I32*$I$24+J32*$J$24+K32*$K$24+L32*$L$24+$M$24*M32+N32*$N$24+$O$24*O32+$P$24*P32+$Q$24*Q32,0) -> 0 | S32: =G32/R32 -> #DIV/0! | X32: =_xlfn.XLOOKUP(C32,$O$124:$O$132,$P$124:$P$132," ") | BA32: =IF(OR(C32=R$7,C32=R$8,C32=R$9,C32=R$10,C32=R$11),'Site Vist fomat (Design)'!I$64,0) -> 0 | BF32: =BE32*2 -> 0
A33: =A32+1 -> 9 | G33: =IF(C33<>0,F33*$F$22/1000,0) -> 0 | R33: =IF(F33<>0,H33*$H$24+I33*$I$24+J33*$J$24+K33*$K$24+L33*$L$24+$M$24*M33+N33*$N$24+$O$24*O33+$P$24*P33+$Q$24*Q33,0) -> 0 | S33: =G33/R33 -> #DIV/0! | X33: =_xlfn.XLOOKUP(C33,$O$124:$O$132,$P$124:$P$132," ") | BA33: =IF(OR(C33=R$7,C33=R$8,C33=R$9,C33=R$10,C33=R$11),'Site Vist fomat (Design)'!J$64,0) -> 0 | BF33: =BE33*2 -> 0
A34: =A33+1 -> 10 | G34: =IF(C34<>0,F34*$F$22/1000,0) -> 0 | R34: =IF(F34<>0,H34*$H$24+I34*$I$24+J34*$J$24+K34*$K$24+L34*$L$24+$M$24*M34+N34*$N$24+$O$24*O34+$P$24*P34+$Q$24*Q34,0) -> 0 | S34: =G34/R34 -> #DIV/0! | X34: =_xlfn.XLOOKUP(C34,$O$124:$O$132,$P$124:$P$132," ") | BA34: =IF(OR(C34=R$7,C34=R$8,C34=R$9,C34=R$10,C34=R$11),'Site Vist fomat (Design)'!K$64,0) -> 0 | BF34: =BE34*2 -> 0
A35: =A34+1 -> 11 | G35: =IF(C35<>0,F35*$F$22/1000,0) -> 0 | R35: =IF(F35<>0,H35*$H$24+I35*$I$24+J35*$J$24+K35*$K$24+L35*$L$24+$M$24*M35+N35*$N$24+$O$24*O35+$P$24*P35+$Q$24*Q35,0) -> 0 | S35: =G35/R35 -> #DIV/0! | X35: =_xlfn.XLOOKUP(C35,$O$124:$O$132,$P$124:$P$132," ") | BA35: =IF(OR(C35=R$7,C35=R$8,C35=R$9,C35=R$10,C35=R$11),'Site Vist fomat (Design)'!L$64,0) -> 0 | BF35: =BE35*2 -> 0
A36: =A35+1 -> 12 | G36: =IF(C36<>0,F36*$F$22/1000,0) -> 0 | R36: =IF(F36<>0,H36*$H$24+I36*$I$24+J36*$J$24+K36*$K$24+L36*$L$24+$M$24*M36+N36*$N$24+$O$24*O36+$P$24*P36+$Q$24*Q36,0) -> 0 | S36: =G36/R36 -> #DIV/0! | X36: =_xlfn.XLOOKUP(C36,$O$124:$O$132,$P$124:$P$132," ") | BA36: =IF(OR(C36=R$7,C36=R$8,C36=R$9,C36=R$10,C36=R$11),'Site Vist fomat (Design)'!M$64,0) -> 0 | BF36: =BE36*2 -> 0
A37: =A36+1 -> 13 | G37: =IF(C37<>0,F37*$F$22/1000,0) -> 0 | R37: =IF(F37<>0,H37*$H$24+I37*$I$24+J37*$J$24+K37*$K$24+L37*$L$24+$M$24*M37+N37*$N$24+$O$24*O37+$P$24*P37+$Q$24*Q37,0) -> 0 | S37: =G37/R37 -> #DIV/0! | X37: =_xlfn.XLOOKUP(C37,$O$124:$O$132,$P$124:$P$132," ") | BA37: =IF(OR(C37=R$7,C37=R$8,C37=R$9,C37=R$10,C37=R$11),'Site Vist fomat (Design)'!N$64,0) -> 0 | BF37: =BE37*2 -> 0
A38: =A37+1 -> 14 | G38: =IF(C38<>0,F38*$F$22/1000,0) -> 0 | R38: =IF(F38<>0,H38*$H$24+I38*$I$24+J38*$J$24+K38*$K$24+L38*$L$24+$M$24*M38+N38*$N$24+$O$24*O38+$P$24*P38+$Q$24*Q38,0) -> 0 | S38: =G38/R38 -> #DIV/0! | X38: =_xlfn.XLOOKUP(C38,$O$124:$O$132,$P$124:$P$132," ") | BA38: =IF(OR(C38=R$7,C38=R$8,C38=R$9,C38=R$10,C38=R$11),'Site Vist fomat (Design)'!O$64,0) -> 0 | BF38: =BE38*2 -> 0
A39: =A38+1 -> 15 | G39: =IF(C39<>0,F39*$F$22/1000,0) -> 0 | R39: =IF(F39<>0,H39*$H$24+I39*$I$24+J39*$J$24+K39*$K$24+L39*$L$24+$M$24*M39+N39*$N$24+$O$24*O39+$P$24*P39+$Q$24*Q39,0) -> 0 | S39: =G39/R39 -> #DIV/0! | X39: =_xlfn.XLOOKUP(C39,$O$124:$O$132,$P$124:$P$132," ") | BA39: =IF(OR(C39=R$7,C39=R$8,C39=R$9,C39=R$10,C39=R$11),'Site Vist fomat (Design)'!P$64,0) -> 0 | BF39: =BE39*2 -> 0
A40: =A39+1 -> 16 | G40: =IF(C40<>0,F40*$F$22/1000,0) -> 0 | R40: =IF(F40<>0,H40*$H$24+I40*$I$24+J40*$J$24+K40*$K$24+L40*$L$24+$M$24*M40+N40*$N$24+$O$24*O40+$P$24*P40+$Q$24*Q40,0) -> 0 | S40: =G40/R40 -> #DIV/0! | X40: =_xlfn.XLOOKUP(C40,$O$124:$O$132,$P$124:$P$132," ") | BA40: =IF(OR(C40=R$7,C40=R$8,C40=R$9,C40=R$10,C40=R$11),'Site Vist fomat (Design)'!Q$64,0) -> 0 | BF40: =BE40*2 -> 0
A41: =A40+1 -> 17 | G41: =IF(C41<>0,F41*$F$22/1000,0) -> 0 | R41: =IF(F41<>0,H41*$H$24+I41*$I$24+J41*$J$24+K41*$K$24+L41*$L$24+$M$24*M41+N41*$N$24+$O$24*O41+$P$24*P41+$Q$24*Q41,0) -> 0 | S41: =G41/R41 -> #DIV/0! | X41: =_xlfn.XLOOKUP(C41,$O$124:$O$132,$P$124:$P$132," ") | BA41: =IF(OR(C41=R$7,C41=R$8,C41=R$9,C41=R$10,C41=R$11),'Site Vist fomat (Design)'!R$64,0) -> 0 | BF41: =BE41*2 -> 0
...

Sheet Cable Calcualtion
A1: Al. CABLE CAPACITY(3.5Core) in Sq.mm | C1: 16 | D1: 25 | E1: 35 | F1: 50 | G1: 70 | H1: 95 | I1: 120 | J1: 150 | K1: 185 | L1: 240 | M1: 300 | N1: 400
C2: 3x 16+16 | D2: 3x25+16 | E2: 3x35+16 | F2: 3x50+25 | G2: 3x70+35 | H2: 3x95+50 | I2: 3x120+70 | J2: 3x150+70 | K2: 3x185+95 | L2: 3x240+120 | M2: 3x300+150 | N2: 3x400+185
A3: Cable Amps in Al. Cond. Run in Ground | C3: 74 | D3: 94 | E3: 113 | F3: 133 | G3: 164 | H3: 196 | I3: 223 | J3: 249 | K3: 282 | L3: 326 | M3: 367 | N3: 418
A4: Cable Amps in Al. Cond. Run in Air | C4: 74 | D4: 96 | E4: 117 | F4: 142 | G4: 179 | H4: 221 | I4: 257 | J4: 292 | K4: 337 | L4: 399 | M4: 455 | N4: 530
A5: Total Derating factorb (K1*K2*K3*K4*K5*K6*K7) | B5: 0.7 | C5: =B5 -> 0.7 | D5: =C5 -> 0.7 | E5: =D5 -> 0.7 | F5: =E5 -> 0.7 | G5: =F5 -> 0.7 | H5: =G5 -> 0.7 | I5: =H5 -> 0.7 | J5: =I5 -> 0.7 | ... N5: =M5 -> 0.7
A6: Derated Current in Ground | C6: =C3*C5 -> 51.8 | D6: =D3*D5 -> 65.8 | E6: =E3*E5 -> 79.1 | F6: =F3*F5 -> 93.1 | G6: =G3*G5 -> 114.8 | H6: =H3*H5 -> 137.2 | I6: =I3*I5 -> 156.1 | J6: =J3*J5 -> 174.3 | ... N6: =N3*N5 -> 292.6
A7: Derated Current in Air | C7: =C4*C5 -> 51.8 | D7: =D4*D5 -> 67.2 | E7: =E4*E5 -> 81.9 | F7: =F4*F5 -> 99.4 | G7: =G4*G5 -> 125.3 | H7: =H4*H5 -> 154.7 | I7: =I4*I5 -> 179.9 | J7: =J4*J5 -> 204.4 | ... N7: =N4*N5 -> 371
A8: Resistance @ 90 degrees in ohm/Km | C8: 2.44 | D8: 1.54 | E8: 1.11 | F8: 0.82 | G8: 0.567 | H8: 0.41 | I8: 0.324 | J8: 0.264 | K8: 0.21 | L8: 0.16 | M8: 0.128 | N8: 0.1
A9: Reactance @ 50HZ in ohm/Km | C9: 0.0808 | D9: 0.0805 | E9: 0.0783 | F9: 0.075 | G9: 0.074 | H9: 0.0724 | I9: 0.0712 | J9: 0.0716 | K9: 0.0718 | L9: 0.071 | M9: 0.0705 | N9: 0.0704
A10: No.of amps need to carry on each phase (Amp) | B10: =A18 -> 196.82973 | C10: =B10 -> 196.82973 | D10: =C10 -> 196.82973 | E10: =D10 -> 196.82973 | F10: =E10 -> 196.82973 | G10: =F10 -> 196.82973 | H10: =G10 -> 196.82973 | I10: =H10 -> 196.82973 | J10: =I10 -> 196.82973 | ... N10: =M10 -> 196.82973
A11: No.of meters for run (Mtrs) | B11: ='Input''s from Initial Design'!X60 -> 170 | C11: =B11 -> 170 | D11: =C11 -> 170 | E11: =D11 -> 170 | F11: =E11 -> 170 | G11: =F11 -> 170 | H11: =G11 -> 170 | I11: =H11 -> 170 | J11: =I11 -> 170 | ... N11: =M11 -> 170
A12: No.of runs | B12: ='Input''s from Initial Design'!Y60 -> 1 | C12: =B12 -> 1 | D12: =C12 -> 1 | E12: =D12 -> 1 | F12: =E12 -> 1 | G12: =F12 -> 1 | H12: =G12 -> 1 | I12: =H12 -> 1 | J12: =I12 -> 1 | ... N12: =M12 -> 1
A13: Operating Voltage | B13: 415 | C13: =+B13 -> 415 | D13: =+C13 -> 415 | E13: =+D13 -> 415 | F13: =+E13 -> 415 | G13: =+F13 -> 415 | H13: =+G13 -> 415 | I13: =+H13 -> 415 | J13: =+I13 -> 415 | ... N13: =+M13 -> 415
A14: Voltage drop of cable | C14: =1.732*C10*(C8/1000*1+C9/1000*0)*C11/C12 -> 141.40909 | D14: =1.732*D10*(D8/1000*1+D9/1000*0)*D11/D12 -> 89.25 | E14: =1.732*E10*(E8/1000*1+E9/1000*0)*E11/E12 -> 64.329545 | F14: =1.732*F10*(F8/1000*1+F9/1000*0)*F11/F12 -> 47.522727 | G14: =1.732*G10*(G8/1000*1+G9/1000*0)*G11/G12 -> 32.860227 | H14: =1.732*H10*(H8/1000*1+H9/1000*0)*H11/H12 -> 23.761364 | I14: =1.732*I10*(I8/1000*1+I9/1000*0)*I11/I12 -> 18.777273 | J14: =1.732*J10*(J8/1000*1+J9/1000*0)*J11/J12 -> 15.3 | ... N14: =1.732*N10*(N8/1000*1+N9/1000*0)*N11/N12 -> 5.7954545
A15: Voltage drop of cable% | C15: =C14/C13 -> 0.3407448 | D15: =D14/D13 -> 0.21506024 | E15: =E14/E13 -> 0.15501095 | F15: =F14/F13 -> 0.1145126 | G15: =G14/G13 -> 0.079181271 | H15: =H14/H13 -> 0.057256298 | I15: =I14/I13 -> 0.04524644 | J15: =J14/J13 -> 0.03686747 | ... N15: =N14/N13 -> 0.013964951
A16: If feasable in Ground | B16: 0.02 | C16: =IF(AND((C10*1.25)<(C6*C12),(C15<$B$16)),"PASS","FAIL") -> FAIL | D16: =IF(AND((D10*1.25)<(D6*D12),(D15<$B$16)),"PASS","FAIL") -> FAIL | E16: =IF(AND((E10*1.25)<(E6*E12),(E15<$B$16)),"PASS","FAIL") -> FAIL | F16: =IF(AND((F10*1.25)<(F6*F12),(F15<$B$16)),"PASS","FAIL") -> FAIL | G16: =IF(AND((G10*1.25)<(G6*G12),(G15<$B$16)),"PASS","FAIL") -> FAIL | H16: =IF(AND((H10*1.1)<(H6*H12),(H15<$B$16)),"PASS","FAIL") -> FAIL | I16: =IF(AND((I10*1.25)<(I6*I12),(I15<$B$16)),"PASS","FAIL") -> FAIL | J16: =IF(AND((J10*1.25)<(J6*J12),(J15<$B$16)),"PASS","FAIL") -> FAIL | K16: =IF(AND((K10*1.25)<(K6*K12),(K15<$B$16)),"PASS","FAIL") -> FAIL | L16: =IF(AND((L10*1.25)<(L6*L12),(L15<$B$16)),"PASS","FAIL") -> FAIL | M16: =IF(AND((M10*1.25)<(M6*M12),(M15<$B$16)),"PASS","FAIL") -> PASS | N16: =IF(AND((N10*1.25)<(N6*N12),(N15<$B$16)),"PASS","FAIL") -> PASS
A17: If feasable in Air | C17: =IF(AND((C10*1.25)<(C7*C12),(C15<$B$16)),"PASS","FAIL") -> FAIL | D17: =IF(AND((D10*1.25)<(D7*D12),(D15<$B$16)),"PASS","FAIL") -> FAIL | E17: =IF(AND((E10*1.25)<(E7*E12),(E15<$B$16)),"PASS","FAIL") -> FAIL | F17: =IF(AND((F10*1.25)<(F7*F12),(F15<$B$16)),"PASS","FAIL") -> FAIL | G17: =IF(AND((G10*1.25)<(G7*G12),(G15<$B$16)),"PASS","FAIL") -> FAIL | H17: =IF(AND((H10*1.25)<(H7*H12),(H15<$B$16)),"PASS","FAIL") -> FAIL | I17: =IF(AND((I10*1.25)<(I7*I12),(I15<$B$16)),"PASS","FAIL") -> FAIL | J17: =IF(AND((J10*1.25)<(J7*J12),(J15<$B$16)),"PASS","FAIL") -> FAIL | ... N17: =IF(AND((N10*1.25)<(N7*N12),(N15<$B$16)),"PASS","FAIL") -> PASS
A18: =('Input''s from Initial Design'!W60*1000/(1.732*440*1)) -> 196.82973 | B18: Amps
E19: 1
A20: If feasable in Ground | B20: =IF(C16="FAIL",IF(D16="FAIL",IF(E16="FAIL",IF(F16="FAIL",IF(G16="FAIL",IF(H16="FAIL",IF(I16="FAIL",IF(J16="FAIL",IF(K16="FAIL",IF(L16="FAIL",IF(M16="FAIL","NO MATCH",$M$1),$L$1),$K$1),$J$1),$I$1),$H$1),$G$1),$F$1),$E$1),$D$1),$C$1) -> 300 | C20: Sqmm.
A21: If feasable in Air | B21: =IF(C17="FAIL",IF(D17="FAIL",IF(E17="FAIL",IF(F17="FAIL",IF(G17="FAIL",IF(H17="FAIL",IF(I17="FAIL",IF(J17="FAIL",IF(K17="FAIL",IF(L17="FAIL",IF(M17="FAIL","NO MATCH",$M$1),$L$1),$K$1),$J$1),$I$1),$H$1),$G$1),$F$1),$E$1),$D$1),$C$1) -> 300 | C21: Sqmm.
A24: Al. CABLE CAPACITY(3.5Core) in Sq.mm | C24: 16 | D24: 25 | E24: 35 | F24: 50 | G24: 70 | H24: 95 | I24: 120 | J24: 150 | K24: 185 | L24: 240 | M24: 300 | N24: 400
C25: 3x 16+16 | D25: 3x25+16 | E25: 3x35+16 | F25: 3x50+25 | G25: 3x70+35 | H25: 3x95+50 | I25: 3x120+70 | J25: 3x150+70 | K25: 3x185+95 | L25: 3x240+120 | M25: 3x300+150 | N25: 3x400+185
A26: Cable Amps in Al. Cond. Run in Ground | C26: 74 | D26: 94 | E26: 113 | F26: 133 | G26: 164 | H26: 196 | I26: 223 | J26: 249 | K26: 282 | L26: 326 | M26: 367 | N26: 418
A27: Cable Amps in Al. Cond. Run in Air | C27: 74 | D27: 96 | E27: 117 | F27: 142 | G27: 179 | H27: 221 | I27: 257 | J27: 292 | K27: 337 | L27: 399 | M27: 455 | N27: 530
A28: Total Derating factorb (K1*K2*K3*K4*K5*K6*K7) | B28: 0.7 | C28: =B28 -> 0.7 | D28: =C28 -> 0.7 | E28: =D28 -> 0.7 | F28: =E28 -> 0.7 | G28: =F28 -> 0.7 | H28: =G28 -> 0.7 | I28: =H28 -> 0.7 | J28: =I28 -> 0.7 | ... N28: =M28 -> 0.7
A29: Derated Current in Ground | C29: =C26*C28 -> 51.8 | D29: =D26*D28 -> 65.8 | E29: =E26*E28 -> 79.1 | F29: =F26*F28 -> 93.1 | G29: =G26*G28 -> 114.8 | H29: =H26*H28 -> 137.2 | I29: =I26*I28 -> 156.1 | J29: =J26*J28 -> 174.3 | ... N29: =N26*N28 -> 292.6
A30: Derated Current in Air | C30: =C27*C28 -> 51.8 | D30: =D27*D28 -> 67.2 | E30: =E27*E28 -> 81.9 | F30: =F27*F28 -> 99.4 | G30: =G27*G28 -> 125.3 | H30: =H27*H28 -> 154.7 | I30: =I27*I28 -> 179.9 | J30: =J27*J28 -> 204.4 | ... N30: =N27*N28 -> 371
A31: Resistance @ 90 degrees in ohm/Km | C31: 2.44 | D31: 1.54 | E31: 1.11 | F31: 0.82 | G31: 0.567 | H31: 0.41 | I31: 0.324 | J31: 0.264 | K31: 0.21 | L31: 0.16 | M31: 0.128 | N31: 0.1
A32: Reactance @ 50HZ in ohm/Km | C32: 0.0808 | D32: 0.0805 | E32: 0.0783 | F32: 0.075 | G32: 0.074 | H32: 0.0724 | I32: 0.0712 | J32: 0.0716 | K32: 0.0718 | L32: 0.071 | M32: 0.0705 | N32: 0.0704
A33: No.of amps need to carry on each phase (Amp) | B33: =A41 -> 196.82973 | C33: =B33 -> 196.82973 | D33: =C33 -> 196.82973 | E33: =D33 -> 196.82973 | F33: =E33 -> 196.82973 | G33: =F33 -> 196.82973 | H33: =G33 -> 196.82973 | I33: =H33 -> 196.82973 | J33: =I33 -> 196.82973 | ... N33: =M33 -> 196.82973
A34: No.of meters for run (Mtrs) | B34: ='Input''s from Initial Design'!X62 -> 220 | C34: =B34 -> 220 | D34: =C34 -> 220 | E34: =D34 -> 220 | F34: =E34 -> 220 | G34: =F34 -> 220 | H34: =G34 -> 220 | I34: =H34 -> 220 | J34: =I34 -> 220 | ... N34: =M34 -> 220
A35: No.of runs | B35: ='Input''s from Initial Design'!Y62 -> 2 | C35: =B35 -> 2 | D35: =C35 -> 2 | E35: =D35 -> 2 | F35: =E35 -> 2 | G35: =F35 -> 2 | H35: =G35 -> 2 | I35: =H35 -> 2 | J35: =I35 -> 2 | ... N35: =M35 -> 2
A36: Operating Voltage | B36: 415 | C36: =+B36 -> 415 | D36: =+C36 -> 415 | E36: =+D36 -> 415 | F36: =+E36 -> 415 | G36: =+F36 -> 415 | H36: =+G36 -> 415 | I36: =+H36 -> 415 | J36: =+I36 -> 415 | ... N36: =+M36 -> 415
A37: Voltage drop of cable | C37: =1.732*C33*(C31/1000*1+C32/1000*0)*C34/C35 -> 91.5 | D37: =1.732*D33*(D31/1000*1+D32/1000*0)*D34/D35 -> 57.75 | E37: =1.732*E33*(E31/1000*1+E32/1000*0)*E34/E35 -> 41.625 | F37: =1.732*F33*(F31/1000*1+F32/1000*0)*F34/F35 -> 30.75 | G37: =1.732*G33*(G31/1000*1+G32/1000*0)*G34/G35 -> 21.2625 | H37: =1.732*H33*(H31/1000*1+H32/1000*0)*H34/H35 -> 15.375 | I37: =1.732*I33*(I31/1000*1+I32/1000*0)*I34/I35 -> 12.15 | J37: =1.732*J33*(J31/1000*1+J32/1000*0)*J34/J35 -> 9.9 | ... N37: =1.732*N33*(N31/1000*1+N32/1000*0)*N34/N35 -> 3.75
A38: Voltage drop of cable% | C38: =C37/C36 -> 0.22048193 | D38: =D37/D36 -> 0.13915663 | E38: =E37/E36 -> 0.1003012 | F38: =F37/F36 -> 0.074096386 | G38: =G37/G36 -> 0.05123494 | H38: =H37/H36 -> 0.037048193 | I38: =I37/I36 -> 0.029277108 | J38: =J37/J36 -> 0.023855422 | ... N38: =N37/N36 -> 0.0090361446
A39: If feasable in Ground | B39: 0.02 | C39: =IF(AND((C33*1.25)<(C29*C35),(C38<$B$16)),"PASS","FAIL") -> FAIL | D39: =IF(AND((D33*1.25)<(D29*D35),(D38<$B$16)),"PASS","FAIL") -> FAIL | E39: =IF(AND((E33*1.25)<(E29*E35),(E38<$B$16)),"PASS","FAIL") -> FAIL | F39: =IF(AND((F33*1.25)<(F29*F35),(F38<$B$16)),"PASS","FAIL") -> FAIL | G39: =IF(AND((G33*1.25)<(G29*G35),(G38<$B$16)),"PASS","FAIL") -> FAIL | H39: =IF(AND((H33*1.1)<(H29*H35),(H38<$B$16)),"PASS","FAIL") -> FAIL | I39: =IF(AND((I33*1.25)<(I29*I35),(I38<$B$16)),"PASS","FAIL") -> FAIL | J39: =IF(AND((J33*1.25)<(J29*J35),(J38<$B$16)),"PASS","FAIL") -> FAIL | K39: =IF(AND((K33*1.25)<(K29*K35),(K38<$B$16)),"PASS","FAIL") -> PASS | L39: =IF(AND((L33*1.25)<(L29*L35),(L38<$B$16)),"PASS","FAIL") -> PASS | M39: =IF(AND((M33*1.25)<(M29*M35),(M38<$B$16)),"PASS","FAIL") -> PASS | N39: =IF(AND((N33*1.25)<(N29*N35),(N38<$B$16)),"PASS","FAIL") -> PASS
A40: If feasable in Air | C40: =IF(AND((C33*1.25)<(C30*C35),(C38<$B$16)),"PASS","FAIL") -> FAIL | D40: =IF(AND((D33*1.25)<(D30*D35),(D38<$B$16)),"PASS","FAIL") -> FAIL | E40: =IF(AND((E33*1.25)<(E30*E35),(E38<$B$16)),"PASS","FAIL") -> FAIL | F40: =IF(AND((F33*1.25)<(F30*F35),(F38<$B$16)),"PASS","FAIL") -> FAIL | G40: =IF(AND((G33*1.25)<(G30*G35),(G38<$B$16)),"PASS","FAIL") -> FAIL | H40: =IF(AND((H33*1.25)<(H30*H35),(H38<$B$16)),"PASS","FAIL") -> FAIL | I40: =IF(AND((I33*1.25)<(I30*I35),(I38<$B$16)),"PASS","FAIL") -> FAIL | J40: =IF(AND((J33*1.25)<(J30*J35),(J38<$B$16)),"PASS","FAIL") -> FAIL | ... N40: =IF(AND((N33*1.25)<(N30*N35),(N38<$B$16)),"PASS","FAIL") -> PASS
A41: =('Input''s from Initial Design'!W62*1000/(1.732*440*1)) -> 196.82973 | B41: Amps
E42: 2
...

Sheet Bidcell BOM (LTS)
B1: Fourth Partner Energy Pvt Ltd | H1: DOC. No: 4PEL/DES-BCB/662 #I01, R00.
H2: Issue Date: 23/02/2026.
H3: Control Copy No. 02.
B4: BID Cell BOM
A5: SALES BOM (415V LT Level)
A6: Sales BOM Summary | E6: Client Name | G6: ='Input''s from BD(Sales)'!B11 -> West Pioneer Properties
A7: Module & Inverters | B7: =F32+F45 -> 19.498053 | C7: per Wp | E7: ='Input''s from BD(Sales)'!A16 -> Plant Type (Capex/Opex) | G7: ='Input''s from BD(Sales)'!B16 -> Capex
A8: ACCB Panel, DCDB, Optimazer & Spare feeder | B8: =F66+F73 -> 0.85972236 | C8: per Wp | E8: State Name | G8: ='Input''s from BD(Sales)'!B10 -> Maharashtra
A9: Module Mounting Structure | B9: =F59 -> 14.72 | C9: per Wp | E9: ='Input''s from Initial Design'!R7 -> Shed | G9: ='Input''s from Initial Design'!S7 -> 0
A10: DC, AC, Control & Communication Cables | B10: =F77+F81+F94+F107+F121 -> 2.7400028 | C10: per Wp | E10: ='Input''s from Initial Design'!R8 -> Long Rail | G10: ='Input''s from Initial Design'!S8 -> 0
A11: Earthing & LA, RMS and BOS | B11: =F132+F194+F305 -> 1.6775452 | C11: per Wp | E11: ='Input''s from Initial Design'!R9 -> RCC | G11: ='Input''s from Initial Design'!S9 -> 0
A12: Rooftop Infra. (Walkways, cable tray, Ladder & Etc.) | B12: =F137+F141+F150+F159+F178 -> 2.6452092 | C12: per Wp | E12: ='Input''s from Initial Design'!R10 -> RCC Raised | G12: ='Input''s from Initial Design'!S10 -> 400.52
A13: Ground Infra. (Fencing & Plant lighting) | B13: =F200 -> 0 | C13: per Wp | E13: ='Input''s from Initial Design'!R11 -> RCC Raised on Pillars | G13: ='Input''s from Initial Design'!S11 -> 0
A14: I&C and Civil works, Spare & Additional Requirements | B14: =F309+F331+F360+F317+F322 -> -14.147494 | C14: per Wp | E14: ='Input''s from Initial Design'!R12 -> Ground Mounted | G14: ='Input''s from Initial Design'!S12 -> 0
A15: Liaisoning, Net metering | B15: =F381 -> 3.7249975 | C15: per Wp | E15: ='Input''s from Initial Design'!R13 -> Parking- Car/Bike | G15: ='Input''s from Initial Design'!S13 -> 0
A16: AMC & Module cleaning | B16: =F393 -> 0 | C16: per Wp | E16: ='Input''s from Initial Design'!R14 -> Parking-Truck/Bus | G16: ='Input''s from Initial Design'!S14 -> 0
A17: Total summary break-up | E17: ='Input''s from Initial Design'!R15 -> Floating | G17: ='Input''s from Initial Design'!S15 -> 0
A18: Plant Cost (Total-A) | B18: =F362 -> 27.993038 | C18: per Wp | E18: Total Plant Capacity | G18: =SUM(G9:G17) -> 400.52
A19: Plant Cost (Total-A ) without Module | B19: =B18-F31 -> 9.9930379 | C19: per Wp | E19: RFP/RFQ Details
A20: Plant Cost (Total-B) | B20: =F383 -> 31.718035 | C20: per Wp | E20: Availability of RFP/RFQ | G20: =IF('Input''s from BD(Sales)'!B15="", "Not Updated", IFERROR('Input''s from BD(Sales)'!B15, "Not Updated")) -> Yes
A21: Selling Cost Excluding of GST (For Capex) | B21: =F399 -> 35.242262 | C21: per Wp | E21: Is Design According RFP/RFQ | G21: =IF('Input''s from Initial Design'!I6="", "Not Updated", IFERROR('Input''s from Initial Design'!I6, "Not Updated")) -> Yes
A22: Selling Cost Including of GST (For Opex) | B22: =F403 -> 38.378823 | C22: per Wp | E22: Is BOM According To RFP/RFQ | G22: No-As per 4PEL Std
A24: Approvals | B24: Name | D24: Date of Review/Approval | F24: Version no. | G24: Reason for Revision
A25: Sale BOM Reviewed By | B25: Sankar | D25: 46164 | F25: V1 | G25: Initial
A26: Sale BOM Approved By | B26: Sankar | D26: 46164
A27: Bidcell BOM Cost valid for 7 days from the date of Approval
A29: Name of the Item's | B29: Unit Cost | C29: Qty | D29: UOM | E29: Total Cost | F29: per Wp | G29: Item's Spec./Scope of Works | H29: Suggested Makes | I29: Remarks/Marketing Comment
A30: SPV Module
A31: Solar Photovoltaic Module | B31: =IFERROR(VLOOKUP('Input''s from Initial Design'!G21,'Input''s from Initial Design'!Y168:Z170,2,0),0)+2 -> 18 | C31: =$G$18 -> 400.52 | D31: kWp | E31: =IF($G$18<1,0,B31*C31*1000) -> 7209360 | F31: =E31/$G$18/1000 -> 18 | G31: ='Input''s from Initial Design'!G21&" - "&'Input''s from Initial Design'!F21&" "&'Input''s from Initial Design'!F22&" Wp" -> Indian ALMM - Renewsys 620 Wp | H31: ='Input''s from Initial Design'!F21 -> Renewsys
A32: Total Cost for PV Module | E32: =IF($G$18<1,0,SUM(E31:E31)) -> 7209360 | F32: =E32/$G$18/1000 -> 18
A33: String Inverters
