Workbook

Sheet Proposal Inputs
A1: FOURTH PARTNER ENERGY — OPEX (BOOT) Proposal Inputs
A2: Yellow cells = your inputs | Pink = mandatory | Blue = optional | Formulas are fine — the document shows the value exactly as Excel displays it
A3: Key | B3: Field | C3: Your Value | D3: Example | E3: Mandatory | F3: Page
A4: 1 · COVER PAGE & EXECUTIVE SUMMARY
A5: PH_001 | B5: Proposed Capacity (kWp) | C5: 499.59 | D5: 600 | E5: MANUAL | F5: 1,2
A6: PH_002 | B6: Installation Technology | C6: Rooftop-Shed | D6: Rooftop - Shed | E6: MANUAL | F6: 1
A7: PH_003 | B7: Estimated Generation (kWh/year) | C7: 687222 | D7: 8,69,211 | E7: MANUAL | F7: 1,4
A8: PH_004 | B8: Guaranteed Generation (kWh/year) | C8: =0.9*C7 -> 618499.8 | D8: 7,82,290 | E8: MANUAL | F8: 4
A9: PH_005 | B9: % Consumption Replaced | D9: ~17% | E9: MANUAL | F9: 4
A10: PH_006 | B10: Net Metering (Yes/No) | C10: Yes | D10: Yes | E10: MANUAL | F10: 4
A11: PH_007 | B11: Key Components — Modules | C11: Renewsys 585+ Wp | D11: Renewsys 595 Wp | E11: MANUAL | F11: 4
A12: PH_008 | B12: Key Components — Inverters | C12: Solis | D12: Solis | E12: MANUAL | F12: 4
A13: PH_009 | B13: Project Timeline | C13: 4 + 1 Months | D13: 4–5 months | E13: MANUAL | F13: 4
A14: PH_010 | B14: Exclusions (Exec summary) | C14: Spare feeder , Internet connectivity | D14: Spare feeder; Net meter infra; Internet connectivity | E14: MANUAL | F14: 4
A15: PH_011 | B15: Commercial — Variable Grid Rate (₹/kWh) | C15: 7.5 | D15: 8.50 | E15: MANUAL | F15: 4
A16: PH_012 | B16: Commercial — Proposed Solar Tariff (₹/kWh) | C16: 5.49 | D16: 6.15 | E16: MANUAL | F16: 4
A17: PH_013 | B17: Commercial — % Savings (1st Year) | C17: 0.268 | D17: ~28% | E17: MANUAL | F17: 4
A18: PH_014 | B18: Commercial — % Grid Consumption Replaced | D18: ~17% | E18: MANUAL | F18: 4
A19: PH_015 | B19: Commercial — CO₂ Reduction (Tons/year) | C19: ='Environmental Benefits'!F17 -> 666.83699 | D19: 816 | E19: AUTOMATIC | F19: 4
A20: PH_016 | B20: Proposal Submitted by | C20: Carl Aaron | carl.aaron@fourthpartner.co | +91- 9551062519 | D20: Carl Aaron | E20: Optional | F20: 4
A21: PH_017 | B21: Proposal Submitted on | C21: =DAY(TODAY())&IF(AND(DAY(TODAY())>=11,DAY(TODAY())<=13),"th",CHOOSE(MIN(5,MOD(DAY(TODAY()),10)+1),"th","st","nd","rd","th"))&" "&TEXT(TODAY(),"mmmm yyyy") -> 10th August 2026 | D21: 31st Jul 2025 | E21: AUTOMATIC | F21: 4
A22: PH_018 | B22: Proposal Validity | C22: 15 days | D22: 15 days | E22: Optional | F22: 4
A23: 2 · SITE DETAILS (1.1 Customer & 1.2 Site)
A24: PH_019 | B24: Customer Name | C24: L&T TLT Galvanizing plant | D24: IFGL Refractories Ltd. | E24: MANUAL | F24: 1,5,13
A25: PH_020 | B25: Customer Address (short) | C25: Neervalur, Tamil Nadu | D25: Kandla, Gujarat | E25: MANUAL | F25: 1,5,13
A26: PH_021 | B26: Contact Person | C26: Mr. Anish | D26: Mr. A. Sharma | E26: MANUAL | F26: 5
A27: PH_022 | B27: Mobile | C27: +91-9645949625 | D27: +91-98XXXXXXXX | E27: MANUAL | F27: 5
A28: PH_023 | B28: Email | C28: ANISH-S@lntecc.com | D28: name@company.com | E28: MANUAL | F28: 5
A29: PH_024 | B29: Site Address (full) | C29: WR22+9R8, Neervalur, Tamil Nadu 631561 | D29: Kandla, Gujarat | E29: MANUAL | F29: 5
A30: PH_025 | B30: Latitude | C30: 12.900828 | D30: 23.0339 | E30: MANUAL | F30: 5
A31: PH_026 | B31: Longitude | C31: 79.802126 | D31: 70.2167 | E31: MANUAL | F31: 5
A32: PH_027 | B32: Type of Installation | C32: Rooftop - Shed | D32: Rooftop - Shed | E32: MANUAL | F32: 5
A33: PH_028 | B33: Type of Roofs | C33: Metal Sheet | D33: Metal Sheet | E33: MANUAL | F33: 5
A34: PH_029 | B34: Availability of Water | C34: Yes | D34: Yes | E34: Optional | F34: 5
A35: PH_030 | B35: Shading | C35: Shadow-free | D35: Shadow-free | E35: Optional | F35: 5
A36: PH_031 | B36: Site GMap Image Path | D36: C:\Proposals\site.png | E36: Optional | F36: 5
A37: 3 · CAPACITY ASSESSMENT (2.1)
A38: PH_032 | B38: Capacity — Shadow-free area: kWp | C38: 499.59 kWp | D38: 620 | E38: Yes | F38: 6
A39: PH_033 | B39: Capacity — Shadow-free area: Notes | C39: Usable shadow-free roof area | D39: Usable shadow-free roof area | E39: Optional | F39: 6
A40: PH_034 | B40: Capacity — Electricity consumption: kWp | C40: 499.59 kWp | D40: 600 | E40: Yes | F40: 6
...

Sheet Environmental Benefits
B2: Environmental Impact Cumulative Impact
B3: Emmission Data (kg/kWh) consumed / emmitted
B4: Coal* | C4: 0.47 | D4: kg/kWh
B5: Cox* | C5: 0.97 | D5: kg/kWh
B6: Sox** | C6: 0.007 | D6: kg/kWh
B7: Nox** | C7: 0.0043 | D7: kg/kWh
B8: Water*** | C8: 2.3 | D8: L/kWh
B9: CO2 absorption by trees**** | C9: =48/2.20462 -> 21.77246 | D9: kgs / tree year
B10: Total Capacity Installed | C10: ='Proposal Inputs'!C5 -> 499.59 | D10: KWp
B11: P50 Value - KWH/kWp per day | C11: 3.77 | D11: KWH/kWp per day
B12: Estimated Generation | C12: =C11*365*C10 -> 687460.82 | D12: KWH
B13: Average CUF | C13: =C12/(C10*365*24) -> 0.15708333 | D13: %
B15: Average reduction when compared to a coal powered plant (Tons / Year)
B16: System | C16: Coal | D16: Sulphur oxides | E16: Nitrogen oxides | F16: Carbon oxides | G16: Water (Litres)
B17: Option | C17: =C10*C13*24*365*C4/10^3 -> 323.10659 | D17: =C10*C13*24*365*C6/10^3 -> 4.8122257 | E17: =C10*C13*24*365*C7/10^3 -> 2.9560815 | F17: =C10*C13*24*365*C5/10^3 -> 666.83699 | G17: =C10*C13*24*365*C8 -> 1581159.9
B19: Carbon offset expressed as number of mature trees planted | C19: =F17/C9*10^3 -> 30627.545
B20: *https://www.eia.gov
B21: **https://www3.epa.gov/ttnchie1/conference/ei20/session5/mmittal.pdf
B22: ***http://breakingenergy.com/2014/03/24/infographic-water-used-by-power-plants/
B23: ****http://www.arborenvironmentalalliance.com/carbon-tree-facts.asp

Sheet Buyout values 
A1: Distributed Opex Portfolio - Buyout values
C2: Input data
B4: Project Life | E4: ='Proposal Inputs'!C77 -> 20 | G4: Other Standard assumptions - not to be changed | K4: Debt assumptions
B5: SD / Group Captive Contribution (INR/ Mwp) | E5: =3500000*0 -> 0 | G5: PR Ratio | H5: 0.76 | K5: Loan amount | L5: 0.7
B6: Tariff (Generation busbar) (INR/kwh) | E6: ='Proposal Inputs'!C123 -> 5.49 | G6: Degradation | H6: 0.0067 | K6: Interest rate | L6: 0.093
B7: Escalation | E7: 0 | G7: Bad debts | H7: 0.02 | K7: Tenor | L7: =MIN(E4*80%,15) -> 15
B8: Generation Yield Year 1 | E8: 3.55 | G8: Insurance cost | H8: 0.0025
B9: Irradiation Year 1 | E9: =E8*365/H5 -> 1704.9342 | G9: Tax Rate | H9: =15%*1.12*1.04 -> 0.17472 | K9: Type of project | L9: Capacity | M9: Cost
G10: IT on sale | H10: 0.34 | K10: Small | L10: <250kwp | M10: 400
B11: Capacity (kWp) | E11: ='Proposal Inputs'!C5 -> 499.59 | G11: Depreciation as co. act | H11: =1/E4 -> 0.05 | K11: Medium | L11: 250kwp-1MWp | M11: 350
B12: EPC and Infra (Rs./Wp) | E12: 30.54 | G12: Depreciation as per IT Act | H12: 0.4 | K12: Large | L12: >1MWp | M12: 250
B13: Land cost | E13: 0 | G13: Additional Depreciation | H13: 0.2
B14: GST @8.9% (Rs./Wp) | E14: =E15-E12 -> 12.08 | G14: O&M | H14: =IF(E11<250,"Small",IF(E11>=1000,"Large","Medium")) -> Medium
B15: Total EPC/Wp (DC) | E15: 42.62 | G15: Base* (Rs/kWp/annum) | H15: =(VLOOKUP(H14,K10:M12,3,0)+29)*1.18 -> 447.22
B16: Financing cost | E16: =E15*70%*1.25% -> 0.372925 | G16: Escalation (% p.a.) | H16: 0.05
B17: Total Project cost/Wp (DC) | E17: =E15+E16 -> 42.992925 | G17: Project ROI | H17: =IRR(L21:L46) -> 0.12092668
B18: Total cost | E18: =E17*E11*1000 -> 21478835 | T18: =S24-S25 -> 897.32892
B19: PROJECT CASHFLOWS | T19: =T18/S22 -> 0.021166542 | AE19: Debt
A20: Year | B20: PR Ratio | C20: Generation | D20: Tenure Check | E20: Tariff | F20: Revenues | G20: O&M Expenses | H20: Insurance | I20: Equipment change | J20: EBITDA | K20: Tax | L20: Cashflow | M20: Opening Bal | N20: Capital Cost | O20: Cashflow | P20: Closing balance | Q20: IT on Sale | R20: Sale Value | S20: Termination value/ kWp (end year) | U20: Net income as per IT Act | V20: Cummulative losses | W20: Tax as per IT | X20: Opening Balance (INR) | Y20: Depreciation (Cos Act) | Z20: Closing Balance | AA20: Opening balance - book value | AB20: Depreciation (IT Act) | AC20: Closing Balance - book value | AE20: Opening balance | AF20: Interest | AG20: EMI | AH20: Closing balance
J21: =-X21 -> -21478835 | L21: =J21 -> -21478835 | P21: =-L21 -> 21478835 | R21: =P21 -> 21478835 | X21: =E18 -> 21478835 | Y21: 0 | Z21: =X21-Y21 -> 21478835 | AA21: =X21 -> 21478835 | AB21: 0 | AC21: =AA21-AB21 -> 21478835
A22: =1 -> 1 | B22: =H5 -> 0.76 | C22: =$E$11*$E$9*B22 -> 647343.74 | D22: =IF(A22<=$E$4,1,0) -> 1 | E22: =E6*D22 -> 5.49 | F22: =C22*E22*(1-$H$7) -> 3482838.8 | G22: =(H15*E11*D22) -> 223426.64 | H22: =Z21*$H$8 -> 53697.089 | I22: =IF(A22>10,$X$21*1%,0)*D22 -> 0 | J22: =F22-SUM(G22:I22) -> 3205715.1 | K22: =W22 -> 0 | L22: =J22-K22 -> 3205715.1 | M22: =P21 -> 21478835 | N22: =M22*$H$17 -> 2597364.4 | O22: =L22 -> 3205715.1 | P22: =M22+N22-O22 -> 20870485 | Q22: =MAX((R22-AC22+V22)*$H$10,0) -> 309004.7 | R22: =P22+Q22 -> 21179489 | S22: =R22/$E$11 -> 42393.742 | T22: =S22*875 -> 37094524 | U22: =J22-AB22-AF22 -> -11679118 | V22: =U22 -> -11679118 | W22: =IF(V22=0,(U22*$H$9),0) -> 0 | X22: =Z21 -> 21478835 | Y22: =IF(X22>0,$X$21*$H$11*D22,0) -> 1073941.8 | Z22: =X22-Y22 -> 20404894 | AA22: =IF(D23=1,AC21,0) -> 21478835 | AB22: =AA22*H12+AA22*H13 -> 12887301 | AC22: =AA22-AB22 -> 8591534.2 | AE22: =X21 -> 21478835 | AF22: =AE22*$L$6 -> 1997531.7 | AG22: =IF(AE22>0,PMT($L$6,($L$7),$AE$22,0,0),0) -> -2712009.6 | AH22: =MAX(AE22+AF22+AG22,0) -> 20764358
A23: =A22+1 -> 2 | B23: =B22*(1-A22*$H$6) -> 0.754908 | C23: =$E$11*$E$9*B23 -> 643006.54 | D23: =IF(A23<=$E$4,1,0) -> 1 | E23: =E22*(1+$E$7)*D23 -> 5.49 | F23: =C23*E23*(1-$H$7) -> 3459503.8 | G23: =G22*(1+$H$16)*D23 -> 234597.97 | H23: =Z22*$H$8 -> 51012.234 | I23: =IF(A23>10,$X$21*1%,0)*D23 -> 0 | J23: =F23-SUM(G23:I23) -> 3173893.6 | K23: =W23 -> 0 | L23: =J23-K23 -> 3173893.6 | M23: =P22 -> 20870485 | N23: =M23*$H$17 -> 2523798.5 | O23: =L23 -> 3173893.6 | P23: =M23+N23-O23 -> 20220390 | Q23: =MAX((R23-AC23+V23)*$H$10,0) -> 614341.84 | R23: =P23+Q23 -> 20834731 | S23: =R23/$E$11 -> 41703.66 | T23: =S23*875 -> 36490702 | U23: =J23-AB23-AF23 -> -2193805.3 | V23: =MIN(V22+U23,0) -> -13872923 | W23: =IF(V23=0,(U23*$H$9),0) -> 0 | X23: =Z22 -> 20404894 | Y23: =IF(X23>0,$X$21*$H$11*D23,0) -> 1073941.8 | Z23: =X23-Y23 -> 19330952 | AA23: =IF(D24=1,AC22,0) -> 8591534.2 | AB23: =AA23*$H$12 -> 3436613.7 | AC23: =AA23-AB23 -> 5154920.5 | AE23: =AH22 -> 20764358 | AF23: =AE23*$L$6 -> 1931085.2 | AG23: =IF(AE23>0,PMT($L$6,($L$7),$AE$22,0,0),0) -> -2712009.6 | AH23: =MAX(AE23+AF23+AG23,0) -> 19983433
A24: =A23+1 -> 3 | B24: =B23*(1-$H$6) -> 0.74985012 | C24: =$E$11*$E$9*B24 -> 638698.4 | D24: =IF(A24<=$E$4,1,0) -> 1 | E24: =E23*(1+$E$7)*D24 -> 5.49 | F24: =C24*E24*(1-$H$7) -> 3436325.1 | G24: =G23*(1+$H$16)*D24 -> 246327.87 | H24: =Z23*$H$8 -> 48327.38 | I24: =IF(A24>10,$X$21*1%,0)*D24 -> 0 | J24: =F24-SUM(G24:I24) -> 3141669.9 | K24: =W24 -> 0 | L24: =J24-K24 -> 3141669.9 | M24: =P23 -> 20220390 | N24: =M24*$H$17 -> 2445184.7 | O24: =L24 -> 3141669.9 | P24: =M24+N24-O24 -> 19523904 | Q24: =MAX((R24-AC24+V24)*$H$10,0) -> 916594.31 | R24: =P24+Q24 -> 20440499 | S24: =R24/$E$11 -> 40914.547 | T24: =S24*875 -> 35800229 | U24: =J24-AB24-AF24 -> -778757.63 | V24: =MIN(V23+U24,0) -> -14651681 | W24: =IF(V24=0,(U24*$H$9),0) -> 0 | X24: =Z23 -> 19330952 | Y24: =IF(X24>0,$X$21*$H$11*D24,0) -> 1073941.8 | Z24: =X24-Y24 -> 18257010 | AA24: =IF(D25=1,AC23,0) -> 5154920.5 | AB24: =AA24*$H$12 -> 2061968.2 | AC24: =AA24-AB24 -> 3092952.3 | AE24: =AH23 -> 19983433 | AF24: =AE24*$L$6 -> 1858459.3 | AG24: =IF(AE24>0,PMT($L$6,($L$7),$AE$22,0,0),0) -> -2712009.6 | AH24: =MAX(AE24+AF24+AG24,0) -> 19129883
A25: =A24+1 -> 4 | B25: =B24*(1-$H$6) -> 0.74482612 | C25: =$E$11*$E$9*B25 -> 634419.12 | D25: =IF(A25<=$E$4,1,0) -> 1 | E25: =E24*(1+$E$7)*D25 -> 5.49 | F25: =C25*E25*(1-$H$7) -> 3413301.7 | G25: =G24*(1+$H$16)*D25 -> 258644.26 | H25: =Z24*$H$8 -> 45642.525 | I25: =IF(A25>10,$X$21*1%,0)*D25 -> 0 | J25: =F25-SUM(G25:I25) -> 3109014.9 | K25: =W25 -> 0 | L25: =J25-K25 -> 3109014.9 | M25: =P24 -> 19523904 | N25: =M25*$H$17 -> 2360961 | O25: =L25 -> 3109014.9 | P25: =M25+N25-O25 -> 18775851 | Q25: =MAX((R25-AC25+V25)*$H$10,0) -> 1216351.7 | R25: =P25+Q25 -> 19992202 | S25: =R25/$E$11 -> 40017.218 | T25: =S25*875 -> 35015066 | U25: =J25-AB25-AF25 -> 92754.911 | V25: =MIN(V24+U25,0) -> -14558926 | W25: =IF(V25=0,(U25*$H$9),0) -> 0 | X25: =Z24 -> 18257010 | Y25: =IF(X25>0,$X$21*$H$11*D25,0) -> 1073941.8 | Z25: =X25-Y25 -> 17183068 | AA25: =IF(D26=1,AC24,0) -> 3092952.3 | AB25: =AA25*$H$12 -> 1237180.9 | AC25: =AA25-AB25 -> 1855771.4 | AE25: =AH24 -> 19129883 | AF25: =AE25*$L$6 -> 1779079.1 | AG25: =IF(AE25>0,PMT($L$6,($L$7),$AE$22,0,0),0) -> -2712009.6 | AH25: =MAX(AE25+AF25+AG25,0) -> 18196952
A26: =A25+1 -> 5 | B26: =B25*(1-$H$6) -> 0.73983579 | C26: =$E$11*$E$9*B26 -> 630168.51 | D26: =IF(A26<=$E$4,1,0) -> 1 | E26: =E25*(1+$E$7)*D26 -> 5.49 | F26: =C26*E26*(1-$H$7) -> 3390432.6 | G26: =G25*(1+$H$16)*D26 -> 271576.48 | H26: =Z25*$H$8 -> 42957.671 | I26: =IF(A26>10,$X$21*1%,0)*D26 -> 0 | J26: =F26-SUM(G26:I26) -> 3075898.5 | K26: =W26 -> 0 | L26: =J26-K26 -> 3075898.5 | M26: =P25 -> 18775851 | N26: =M26*$H$17 -> 2270501.4 | O26: =L26 -> 3075898.5 | P26: =M26+N26-O26 -> 17970453 | Q26: =MAX((R26-AC26+V26)*$H$10,0) -> 1514204.4 | R26: =P26+Q26 -> 19484658 | S26: =R26/$E$11 -> 39001.297 | T26: =S26*875 -> 34126135 | U26: =J26-AB26-AF26 -> 641273.33 | V26: =MIN(V25+U26,0) -> -13917653 | W26: =IF(V26=0,(U26*$H$9),0) -> 0 | X26: =Z25 -> 17183068 | Y26: =IF(X26>0,$X$21*$H$11*D26,0) -> 1073941.8 | Z26: =X26-Y26 -> 16109127 | AA26: =IF(D27=1,AC25,0) -> 1855771.4 | AB26: =AA26*$H$12 -> 742308.55 | AC26: =AA26-AB26 -> 1113462.8 | AE26: =AH25 -> 18196952 | AF26: =AE26*$L$6 -> 1692316.6 | AG26: =IF(AE26>0,PMT($L$6,($L$7),$AE$22,0,0),0) -> -2712009.6 | AH26: =MAX(AE26+AF26+AG26,0) -> 17177259
A27: =A26+1 -> 6 | B27: =B26*(1-$H$6) -> 0.73487889 | C27: =$E$11*$E$9*B27 -> 625946.38 | D27: =IF(A27<=$E$4,1,0) -> 1 | E27: =E26*(1+$E$7)*D27 -> 5.49 | F27: =C27*E27*(1-$H$7) -> 3367716.7 | G27: =G26*(1+$H$16)*D27 -> 285155.3 | H27: =Z26*$H$8 -> 40272.816 | I27: =IF(A27>10,$X$21*1%,0)*D27 -> 0 | J27: =F27-SUM(G27:I27) -> 3042288.6 | K27: =W27 -> 0 | L27: =J27-K27 -> 3042288.6 | M27: =P26 -> 17970453 | N27: =M27*$H$17 -> 2173107.3 | O27: =L27 -> 3042288.6 | P27: =M27+N27-O27 -> 17101272 | Q27: =MAX((R27-AC27+V27)*$H$10,0) -> 1810737.1 | R27: =P27+Q27 -> 18912009 | S27: =R27/$E$11 -> 37855.06 | T27: =S27*875 -> 33123177 | U27: =J27-AB27-AF27 -> 999418.33 | V27: =MIN(V26+U27,0) -> -12918234 | W27: =IF(V27=0,(U27*$H$9),0) -> 0 | X27: =Z26 -> 16109127 | Y27: =IF(X27>0,$X$21*$H$11*D27,0) -> 1073941.8 | Z27: =X27-Y27 -> 15035185 | AA27: =IF(D28=1,AC26,0) -> 1113462.8 | AB27: =AA27*$H$12 -> 445385.13 | AC27: =AA27-AB27 -> 668077.7 | AE27: =AH26 -> 17177259 | AF27: =AE27*$L$6 -> 1597485.1 | AG27: =IF(AE27>0,PMT($L$6,($L$7),$AE$22,0,0),0) -> -2712009.6 | AH27: =MAX(AE27+AF27+AG27,0) -> 16062735
A28: =A27+1 -> 7 | B28: =B27*(1-$H$6) -> 0.7299552 | C28: =$E$11*$E$9*B28 -> 621752.54 | D28: =IF(A28<=$E$4,1,0) -> 1 | E28: =E27*(1+$E$7)*D28 -> 5.49 | F28: =C28*E28*(1-$H$7) -> 3345153 | G28: =G27*(1+$H$16)*D28 -> 299413.07 | H28: =Z27*$H$8 -> 37587.962 | I28: =IF(A28>10,$X$21*1%,0)*D28 -> 0 | J28: =F28-SUM(G28:I28) -> 3008152 | K28: =W28 -> 0 | L28: =J28-K28 -> 3008152 | M28: =P27 -> 17101272 | N28: =M28*$H$17 -> 2068000.1 | O28: =L28 -> 3008152 | P28: =M28+N28-O28 -> 16161120 | Q28: =MAX((R28-AC28+V28)*$H$10,0) -> 2106519.5 | R28: =P28+Q28 -> 18267640 | S28: =R28/$E$11 -> 36565.263 | T28: =S28*875 -> 31994605 | U28: =J28-AB28-AF28 -> 1247086.5 | V28: =MIN(V27+U28,0) -> -11671148 | W28: =IF(V28=0,(U28*$H$9),0) -> 0 | X28: =Z27 -> 15035185 | Y28: =IF(X28>0,$X$21*$H$11*D28,0) -> 1073941.8 | Z28: =X28-Y28 -> 13961243 | AA28: =IF(D29=1,AC27,0) -> 668077.7 | AB28: =AA28*$H$12 -> 267231.08 | AC28: =AA28-AB28 -> 400846.62 | AE28: =AH27 -> 16062735 | AF28: =AE28*$L$6 -> 1493834.4 | AG28: =IF(AE28>0,PMT($L$6,($L$7),$AE$22,0,0),0) -> -2712009.6 | AH28: =MAX(AE28+AF28+AG28,0) -> 14844560
A29: =A28+1 -> 8 | B29: =B28*(1-$H$6) -> 0.7250645 | C29: =$E$11*$E$9*B29 -> 617586.8 | D29: =IF(A29<=$E$4,1,0) -> 1 | E29: =E28*(1+$E$7)*D29 -> 5.49 | F29: =C29*E29*(1-$H$7) -> 3322740.5 | G29: =G28*(1+$H$16)*D29 -> 314383.72 | H29: =Z28*$H$8 -> 34903.108 | I29: =IF(A29>10,$X$21*1%,0)*D29 -> 0 | J29: =F29-SUM(G29:I29) -> 2973453.7 | K29: =W29 -> 0 | L29: =J29-K29 -> 2973453.7 | M29: =P28 -> 16161120 | N29: =M29*$H$17 -> 1954310.7 | O29: =L29 -> 2973453.7 | P29: =M29+N29-O29 -> 15141977 | Q29: =MAX((R29-AC29+V29)*$H$10,0) -> 2402096.2 | R29: =P29+Q29 -> 17544074 | S29: =R29/$E$11 -> 35116.943 | T29: =S29*875 -> 30727325 | U29: =J29-AB29-AF29 -> 1432570.9 | V29: =MIN(V28+U29,0) -> -10238577 | W29: =IF(V29=0,(U29*$H$9),0) -> 0 | X29: =Z28 -> 13961243 | Y29: =IF(X29>0,$X$21*$H$11*D29,0) -> 1073941.8 | Z29: =X29-Y29 -> 12887301 | AA29: =IF(D30=1,AC28,0) -> 400846.62 | AB29: =AA29*$H$12 -> 160338.65 | AC29: =AA29-AB29 -> 240507.97 | AE29: =AH28 -> 14844560 | AF29: =AE29*$L$6 -> 1380544.1 | AG29: =IF(AE29>0,PMT($L$6,($L$7),$AE$22,0,0),0) -> -2712009.6 | AH29: =MAX(AE29+AF29+AG29,0) -> 13513094
A30: =A29+1 -> 9 | B30: =B29*(1-$H$6) -> 0.72020657 | C30: =$E$11*$E$9*B30 -> 613448.96 | D30: =IF(A30<=$E$4,1,0) -> 1 | E30: =E29*(1+$E$7)*D30 -> 5.49 | F30: =C30*E30*(1-$H$7) -> 3300478.1 | G30: =G29*(1+$H$16)*D30 -> 330102.91 | H30: =Z29*$H$8 -> 32218.253 | I30: =IF(A30>10,$X$21*1%,0)*D30 -> 0 | J30: =F30-SUM(G30:I30) -> 2938157 | K30: =W30 -> 0 | L30: =J30-K30 -> 2938157 | M30: =P29 -> 15141977 | N30: =M30*$H$17 -> 1831069.1 | O30: =L30 -> 2938157 | P30: =M30+N30-O30 -> 14034890 | Q30: =MAX((R30-AC30+V30)*$H$10,0) -> 2697974.2 | R30: =P30+Q30 -> 16732864 | S30: =R30/$E$11 -> 33493.192 | T30: =S30*875 -> 29306543 | U30: =J30-AB30-AF30 -> 1585236 | V30: =MIN(V29+U30,0) -> -8653340.7 | W30: =IF(V30=0,(U30*$H$9),0) -> 0 | X30: =Z29 -> 12887301 | Y30: =IF(X30>0,$X$21*$H$11*D30,0) -> 1073941.8 | Z30: =X30-Y30 -> 11813359 | AA30: =IF(D31=1,AC29,0) -> 240507.97 | AB30: =AA30*$H$12 -> 96203.188 | AC30: =AA30-AB30 -> 144304.78 | AE30: =AH29 -> 13513094 | AF30: =AE30*$L$6 -> 1256717.8 | AG30: =IF(AE30>0,PMT($L$6,($L$7),$AE$22,0,0),0) -> -2712009.6 | AH30: =MAX(AE30+AF30+AG30,0) -> 12057802
A31: =A30+1 -> 10 | B31: =B30*(1-$H$6) -> 0.71538118 | C31: =$E$11*$E$9*B31 -> 609338.86 | D31: =IF(A31<=$E$4,1,0) -> 1 | E31: =E30*(1+$E$7)*D31 -> 5.49 | F31: =C31*E31*(1-$H$7) -> 3278364.9 | G31: =G30*(1+$H$16)*D31 -> 346608.05 | H31: =Z30*$H$8 -> 29533.399 | I31: =IF(A31>10,$X$21*1%,0)*D31 -> 0 | J31: =F31-SUM(G31:I31) -> 2902223.5 | K31: =W31 -> 0 | L31: =J31-K31 -> 2902223.5 | M31: =P30 -> 14034890 | N31: =M31*$H$17 -> 1697192.7 | O31: =L31 -> 2902223.5 | P31: =M31+N31-O31 -> 12829859 | Q31: =MAX((R31-AC31+V31)*$H$10,0) -> 2994607.2 | R31: =P31+Q31 -> 15824466 | S31: =R31/$E$11 -> 31674.905 | T31: =S31*875 -> 27715542 | U31: =J31-AB31-AF31 -> 1723125.9 | V31: =MIN(V30+U31,0) -> -6930214.8 | W31: =IF(V31=0,(U31*$H$9),0) -> 0 | X31: =Z30 -> 11813359 | Y31: =IF(X31>0,$X$21*$H$11*D31,0) -> 1073941.8 | Z31: =X31-Y31 -> 10739418 | AA31: =IF(D32=1,AC30,0) -> 144304.78 | AB31: =AA31*$H$12 -> 57721.913 | AC31: =AA31-AB31 -> 86582.869 | AE31: =AH30 -> 12057802 | AF31: =AE31*$L$6 -> 1121375.6 | AG31: =IF(AE31>0,PMT($L$6,($L$7),$AE$22,0,0),0) -> -2712009.6 | AH31: =MAX(AE31+AF31+AG31,0) -> 10467169
A32: =A31+1 -> 11 | B32: =B31*(1-$H$6) -> 0.71058813 | C32: =$E$11*$E$9*B32 -> 605256.29 | D32: =IF(A32<=$E$4,1,0) -> 1 | E32: =E31*(1+$E$7)*D32 -> 5.49 | F32: =C32*E32*(1-$H$7) -> 3256399.9 | G32: =G31*(1+$H$16)*D32 -> 363938.45 | H32: =Z31*$H$8 -> 26848.544 | I32: =IF(A32>10,$X$21*1%,0)*D32 -> 214788.35 | J32: =F32-SUM(G32:I32) -> 2650824.5 | K32: =W32 -> 0 | L32: =J32-K32 -> 2650824.5 | M32: =P31 -> 12829859 | N32: =M32*$H$17 -> 1551472.3 | O32: =L32 -> 2650824.5 | P32: =M32+N32-O32 -> 11730506 | Q32: =MAX((R32-AC32+V32)*$H$10,0) -> 3292378 | R32: =P32+Q32 -> 15022884 | S32: =R32/$E$11 -> 30070.427 | T32: =S32*875 -> 26311623 | U32: =J32-AB32-AF32 -> 1642744.7 | V32: =MIN(V31+U32,0) -> -5287470.1 | W32: =IF(V32=0,(U32*$H$9),0) -> 0 | X32: =Z31 -> 10739418 | Y32: =IF(X32>0,$X$21*$H$11*D32,0) -> 1073941.8 | Z32: =X32-Y32 -> 9665475.9 | AA32: =IF(D33=1,AC31,0) -> 86582.869 | AB32: =AA32*$H$12 -> 34633.148 | AC32: =AA32-AB32 -> 51949.722 | AE32: =AH31 -> 10467169 | AF32: =AE32*$L$6 -> 973446.67 | AG32: =IF(AE32>0,PMT($L$6,($L$7),$AE$22,0,0),0) -> -2712009.6 | AH32: =MAX(AE32+AF32+AG32,0) -> 8728605.6
A33: =A32+1 -> 12 | B33: =B32*(1-$H$6) -> 0.70582719 | C33: =$E$11*$E$9*B33 -> 601201.07 | D33: =IF(A33<=$E$4,1,0) -> 1 | E33: =E32*(1+$E$7)*D33 -> 5.49 | F33: =C33*E33*(1-$H$7) -> 3234582 | G33: =G32*(1+$H$16)*D33 -> 382135.38 | H33: =Z32*$H$8*D33 -> 24163.69 | I33: =IF(A33>10,$X$21*1%,0)*D33 -> 214788.35 | J33: =F33-SUM(G33:I33) -> 2613494.6 | K33: =W33 -> 0 | L33: =J33-K33 -> 2613494.6 | M33: =P32 -> 11730506 | N33: =M33*$H$17 -> 1418531.3 | O33: =L33 -> 2613494.6 | P33: =M33+N33-O33 -> 10535543 | Q33: =MAX((R33-AC33+V33)*$H$10,0) -> 3604956.9 | R33: =P33+Q33 -> 14140500 | S33: =R33/$E$11 -> 28304.21 | T33: =S33*875 -> 24766183 | U33: =J33-AB33-AF33 -> 1780954.4 | V33: =MIN(V32+U33,0) -> -3506515.7 | W33: =IF(V33=0,(U33*$H$9),0) -> 0 | X33: =Z32 -> 9665475.9 | Y33: =IF(X33>0,$X$21*$H$11*D33,0) -> 1073941.8 | Z33: =X33-Y33 -> 8591534.2 | AA33: =IF(D34=1,AC32,0) -> 51949.722 | AB33: =AA33*$H$12 -> 20779.889 | AC33: =AA33-AB33 -> 31169.833 | AE33: =AH32 -> 8728605.6 | AF33: =AE33*$L$6 -> 811760.32 | AG33: =IF(AE33>0,PMT($L$6,($L$7),$AE$22,0,0),0) -> -2712009.6 | AH33: =MAX(AE33+AF33+AG33,0) -> 6828356.3
A34: =A33+1 -> 13 | B34: =B33*(1-$H$6) -> 0.70109814 | C34: =$E$11*$E$9*B34 -> 597173.02 | D34: =IF(A34<=$E$4,1,0) -> 1 | E34: =E33*(1+$E$7)*D34 -> 5.49 | F34: =C34*E34*(1-$H$7) -> 3212910.3 | G34: =G33*(1+$H$16)*D34 -> 401242.14 | H34: =Z33*$H$8*D34 -> 21478.835 | I34: =IF(A34>10,$X$21*1%,0)*D34 -> 214788.35 | J34: =F34-SUM(G34:I34) -> 2575401 | K34: =W34 -> 0 | L34: =J34-K34 -> 2575401 | M34: =P33 -> 10535543 | N34: =M34*$H$17 -> 1274028.3 | O34: =L34 -> 2575401 | P34: =M34+N34-O34 -> 9234170.5 | Q34: =MAX((R34-AC34+V34)*$H$10,0) -> 3934134.2 | R34: =P34+Q34 -> 13168305 | S34: =R34/$E$11 -> 26358.223 | T34: =S34*875 -> 23063445 | U34: =J34-AB34-AF34 -> 1927895.9 | V34: =MIN(V33+U34,0) -> -1578619.9 | W34: =IF(V34=0,(U34*$H$9),0) -> 0 | X34: =Z33 -> 8591534.2 | Y34: =IF(X34>0,$X$21*$H$11*D34,0) -> 1073941.8 | Z34: =X34-Y34 -> 7517592.4 | AA34: =IF(D35=1,AC33,0) -> 31169.833 | AB34: =AA34*$H$12 -> 12467.933 | AC34: =AA34-AB34 -> 18701.9 | AE34: =AH33 -> 6828356.3 | AF34: =AE34*$L$6 -> 635037.14 | AG34: =IF(AE34>0,PMT($L$6,($L$7),$AE$22,0,0),0) -> -2712009.6 | AH34: =MAX(AE34+AF34+AG34,0) -> 4751383.9
A35: =A34+1 -> 14 | B35: =B34*(1-$H$6) -> 0.69640079 | C35: =$E$11*$E$9*B35 -> 593171.96 | D35: =IF(A35<=$E$4,1,0) -> 1 | E35: =E34*(1+$E$7)*D35 -> 5.49 | F35: =C35*E35*(1-$H$7) -> 3191383.8 | G35: =G34*(1+$H$16)*D35 -> 421304.25 | H35: =Z34*$H$8*D35 -> 18793.981 | I35: =IF(A35>10,$X$21*1%,0)*D35 -> 214788.35 | J35: =F35-SUM(G35:I35) -> 2536497.2 | K35: =W35 -> 364664.71 | L35: =J35-K35 -> 2171832.5 | M35: =P34 -> 9234170.5 | N35: =M35*$H$17 -> 1116657.6 | O35: =L35 -> 2171832.5 | P35: =M35+N35-O35 -> 8178995.6 | Q35: =MAX((R35-AC35+V35)*$H$10,0) -> 4207641.4 | R35: =P35+Q35 -> 12386637 | S35: =R35/$E$11 -> 24793.605 | T35: =S35*875 -> 21694404 | U35: =J35-AB35-AF35 -> 2087137.7 | V35: =MIN(V34+U35,0) -> 0 | W35: =IF(V35=0,(U35*$H$9),0) -> 364664.71 | X35: =Z34 -> 7517592.4 | Y35: =IF(X35>0,$X$21*$H$11*D35,0) -> 1073941.8 | Z35: =X35-Y35 -> 6443650.6 | AA35: =IF(D36=1,AC34,0) -> 18701.9 | AB35: =AA35*$H$12 -> 7480.7599 | AC35: =AA35-AB35 -> 11221.14 | AE35: =AH34 -> 4751383.9 | AF35: =AE35*$L$6 -> 441878.7 | AG35: =IF(AE35>0,PMT($L$6,($L$7),$AE$22,0,0),0) -> -2712009.6 | AH35: =MAX(AE35+AF35+AG35,0) -> 2481253
A36: =A35+1 -> 15 | B36: =B35*(1-$H$6) -> 0.6917349 | C36: =$E$11*$E$9*B36 -> 589197.71 | D36: =IF(A36<=$E$4,1,0) -> 1 | E36: =E35*(1+$E$7)*D36 -> 5.49 | F36: =C36*E36*(1-$H$7) -> 3170001.5 | G36: =G35*(1+$H$16)*D36 -> 442369.46 | H36: =Z35*$H$8*D36 -> 16109.127 | I36: =IF(A36>10,$X$21*1%,0)*D36 -> 214788.35 | J36: =F36-SUM(G36:I36) -> 2496734.6 | K36: =W36 -> 395127.46 | L36: =J36-K36 -> 2101607.1 | M36: =P35 -> 8178995.6 | N36: =M36*$H$17 -> 989058.82 | O36: =L36 -> 2101607.1 | P36: =M36+N36-O36 -> 7066447.3 | Q36: =MAX((R36-AC36+V36)*$H$10,0) -> 3636822.7 | R36: =P36+Q36 -> 10703270 | S36: =R36/$E$11 -> 21424.108 | T36: =S36*875 -> 18746094 | U36: =J36-AB36-AF36 -> 2261489.6 | V36: =MIN(V35+U36,0) -> 0 | W36: =IF(V36=0,(U36*$H$9),0) -> 395127.46 | X36: =Z35 -> 6443650.6 | Y36: =IF(X36>0,$X$21*$H$11*D36,0) -> 1073941.8 | Z36: =X36-Y36 -> 5369708.9 | AA36: =IF(D37=1,AC35,0) -> 11221.14 | AB36: =AA36*$H$12 -> 4488.456 | AC36: =AA36-AB36 -> 6732.6839 | AE36: =AH35 -> 2481253 | AF36: =AE36*$L$6 -> 230756.53 | AG36: =IF(AE36>0,PMT($L$6,($L$7),$AE$22,0,0),0) -> -2712009.6 | AH36: =MAX(AE36+AF36+AG36,0) -> 0
A37: =A36+1 -> 16 | B37: =B36*(1-$H$6) -> 0.68710028 | C37: =$E$11*$E$9*B37 -> 585250.09 | D37: =IF(A37<=$E$4,1,0) -> 1 | E37: =E36*(1+$E$7)*D37 -> 5.49 | F37: =C37*E37*(1-$H$7) -> 3148762.5 | G37: =G36*(1+$H$16)*D37 -> 464487.94 | H37: =Z36*$H$8*D37 -> 13424.272 | I37: =IF(A37>10,$X$21*1%,0)*D37 -> 214788.35 | J37: =F37-SUM(G37:I37) -> 2456062 | K37: =W37 -> 428652.61 | L37: =J37-K37 -> 2027409.3 | M37: =P36 -> 7066447.3 | N37: =M37*$H$17 -> 854522.05 | O37: =L37 -> 2027409.3 | P37: =M37+N37-O37 -> 5893560 | Q37: =MAX((R37-AC37+V37)*$H$10,0) -> 3033995.4 | R37: =P37+Q37 -> 8927555.4 | S37: =R37/$E$11 -> 17869.764 | T37: =S37*875 -> 15636044 | U37: =J37-AB37-AF37 -> 2453368.9 | V37: =MIN(V36+U37,0) -> 0 | W37: =IF(V37=0,(U37*$H$9),0) -> 428652.61 | X37: =Z36 -> 5369708.9 | Y37: =IF(X37>0,$X$21*$H$11*D37,0) -> 1073941.8 | Z37: =X37-Y37 -> 4295767.1 | AA37: =IF(D38=1,AC36,0) -> 6732.6839 | AB37: =AA37*$H$12 -> 2693.0736 | AC37: =AA37-AB37 -> 4039.6104 | AE37: =AH36 -> 0 | AF37: =AE37*$L$6 -> 0 | AG37: =IF(AE37>0,PMT($L$6,($L$7),$AE$22,0,0),0) -> 0 | AH37: =MAX(AE37+AF37+AG37,0) -> 0
A38: =A37+1 -> 17 | B38: =B37*(1-$H$6) -> 0.68249671 | C38: =$E$11*$E$9*B38 -> 581328.91 | D38: =IF(A38<=$E$4,1,0) -> 1 | E38: =E37*(1+$E$7)*D38 -> 5.49 | F38: =C38*E38*(1-$H$7) -> 3127665.8 | G38: =G37*(1+$H$16)*D38 -> 487712.33 | H38: =Z37*$H$8*D38 -> 10739.418 | I38: =IF(A38>10,$X$21*1%,0)*D38 -> 214788.35 | J38: =F38-SUM(G38:I38) -> 2414425.7 | K38: =W38 -> 421566.14 | L38: =J38-K38 -> 1992859.6 | M38: =P37 -> 5893560 | N38: =M38*$H$17 -> 712688.67 | O38: =L38 -> 1992859.6 | P38: =M38+N38-O38 -> 4613389.1 | Q38: =MAX((R38-AC38+V38)*$H$10,0) -> 2375345.8 | R38: =P38+Q38 -> 6988734.9 | S38: =R38/$E$11 -> 13988.941 | T38: =S38*875 -> 12240323 | U38: =J38-AB38-AF38 -> 2412809.9 | V38: =MIN(V37+U38,0) -> 0 | W38: =IF(V38=0,(U38*$H$9),0) -> 421566.14 | X38: =Z37 -> 4295767.1 | Y38: =IF(X38>0,$X$21*$H$11*D38,0) -> 1073941.8 | Z38: =X38-Y38 -> 3221825.3 | AA38: =IF(D39=1,AC37,0) -> 4039.6104 | AB38: =AA38*$H$12 -> 1615.8441 | AC38: =AA38-AB38 -> 2423.7662 | AE38: =AH37 -> 0 | AF38: =AE38*$L$6 -> 0 | AG38: =IF(AE38>0,PMT($L$6,($L$7),$AE$22,0,0),0) -> 0 | AH38: =MAX(AE38+AF38+AG38,0) -> 0
A39: =A38+1 -> 18 | B39: =B38*(1-$H$6) -> 0.67792398 | C39: =$E$11*$E$9*B39 -> 577434.01 | D39: =IF(A39<=$E$4,1,0) -> 1 | E39: =E38*(1+$E$7)*D39 -> 5.49 | F39: =C39*E39*(1-$H$7) -> 3106710.4 | G39: =G38*(1+$H$16)*D39 -> 512097.95 | H39: =Z38*$H$8*D39 -> 8054.5633 | I39: =IF(A39>10,$X$21*1%,0)*D39 -> 214788.35 | J39: =F39-SUM(G39:I39) -> 2371769.6 | K39: =W39 -> 414226.19 | L39: =J39-K39 -> 1957543.4 | M39: =P38 -> 4613389.1 | N39: =M39*$H$17 -> 557881.85 | O39: =L39 -> 1957543.4 | P39: =M39+N39-O39 -> 3213727.6 | Q39: =MAX((R39-AC39+V39)*$H$10,0) -> 1654807.5 | R39: =P39+Q39 -> 4868535.1 | S39: =R39/$E$11 -> 9745.0611 | T39: =S39*875 -> 8526928.5 | U39: =J39-AB39-AF39 -> 2370800.1 | V39: =MIN(V38+U39,0) -> 0 | W39: =IF(V39=0,(U39*$H$9),0) -> 414226.19 | X39: =Z38 -> 3221825.3 | Y39: =IF(X39>0,$X$21*$H$11*D39,0) -> 1073941.8 | Z39: =X39-Y39 -> 2147883.5 | AA39: =IF(D40=1,AC38,0) -> 2423.7662 | AB39: =AA39*$H$12 -> 969.50649 | AC39: =AA39-AB39 -> 1454.2597 | AE39: =AH38 -> 0 | AF39: =AE39*$L$6 -> 0 | AG39: =IF(AE39>0,PMT($L$6,($L$7),$AE$22,0,0),0) -> 0 | AH39: =MAX(AE39+AF39+AG39,0) -> 0
A40: =A39+1 -> 19 | B40: =B39*(1-$H$6) -> 0.67338189 | C40: =$E$11*$E$9*B40 -> 573565.2 | D40: =IF(A40<=$E$4,1,0) -> 1 | E40: =E39*(1+$E$7)*D40 -> 5.49 | F40: =C40*E40*(1-$H$7) -> 3085895.5 | G40: =G39*(1+$H$16)*D40 -> 537702.85 | H40: =Z39*$H$8*D40 -> 5369.7089 | I40: =IF(A40>10,$X$21*1%,0)*D40 -> 214788.35 | J40: =F40-SUM(G40:I40) -> 2328034.6 | K40: =W40 -> 406652.57 | L40: =J40-K40 -> 1921382 | M40: =P39 -> 3213727.6 | N40: =M40*$H$17 -> 388625.42 | O40: =L40 -> 1921382 | P40: =M40+N40-O40 -> 1680971 | Q40: =MAX((R40-AC40+V40)*$H$10,0) -> 865505.27 | R40: =P40+Q40 -> 2546476.3 | S40: =R40/$E$11 -> 5097.1323 | T40: =S40*875 -> 4459990.7 | U40: =J40-AB40-AF40 -> 2327452.9 | V40: =MIN(V39+U40,0) -> 0 | W40: =IF(V40=0,(U40*$H$9),0) -> 406652.57 | X40: =Z39 -> 2147883.5 | Y40: =IF(X40>0,$X$21*$H$11*D40,0) -> 1073941.8 | Z40: =X40-Y40 -> 1073941.8 | AA40: =IF(D41=1,AC39,0) -> 1454.2597 | AB40: =AA40*$H$12 -> 581.70389 | AC40: =AA40-AB40 -> 872.55584 | AE40: =AH39 -> 0 | AF40: =AE40*$L$6 -> 0 | AG40: =IF(AE40>0,PMT($L$6,($L$7),$AE$22,0,0),0) -> 0 | AH40: =MAX(AE40+AF40+AG40,0) -> 0
A41: =A40+1 -> 20 | B41: =B40*(1-$H$6) -> 0.66887023 | C41: =$E$11*$E$9*B41 -> 569722.31 | D41: =IF(A41<=$E$4,1,0) -> 1 | E41: =E40*(1+$E$7)*D41 -> 5.49 | F41: =C41*E41*(1-$H$7) -> 3065220 | G41: =G40*(1+$H$16)*D41 -> 564587.99 | H41: =Z40*$H$8*D41 -> 2684.8544 | I41: =IF(A41>10,$X$21*1%,0)*D41 -> 214788.35 | J41: =F41-SUM(G41:I41) -> 2283158.8 | K41: =W41 -> 398913.5 | L41: =J41-K41 -> 1884245.3 | M41: =P40 -> 1680971 | N41: =M41*$H$17 -> 203274.25 | O41: =L41 -> 1884245.3 | P41: =M41+N41-O41 -> 1.4994293e-07 | Q41: =MAX((R41-AC41+V41)*$H$10,0) -> 7.724333e-08 | R41: =P41+Q41 -> 2.2718626e-07 | S41: =R41/$E$11 -> 4.5474542e-10 | T41: =S41*875 -> 3.9790224e-07 | U41: =J41-AB41-AF41 -> 2283158.8 | V41: =MIN(V40+U41,0) -> 0 | W41: =IF(V41=0,(U41*$H$9),0) -> 398913.5 | X41: =Z40 -> 1073941.8 | Y41: =IF(X41>0,$X$21*$H$11*D41,0) -> 1073941.8 | Z41: =X41-Y41 -> 4.1909516e-09 | AA41: =IF(D42=1,AC40,0) -> 0 | AB41: =AA41*$H$12 -> 0 | AC41: =AA41-AB41 -> 0 | AE41: =AH40 -> 0 | AF41: =AE41*$L$6 -> 0 | AG41: =IF(AE41>0,PMT($L$6,($L$7),$AE$22,0,0),0) -> 0 | AH41: =MAX(AE41+AF41+AG41,0) -> 0
...
